Workbook
Name く５４: #REF!
Name く５４: 資金運用表!#REF!
Name く５４: 資金運用表!#REF!
Name く５４: #REF!
Name く５４: #REF!
Name 様式: #REF!

Sheet 財務諸表（入力）
A1: 企業名 : | O1: =TODAY() -> 46071
A2: 貸 借 対 照 表 （ Ｂ ／ Ｓ ）
O3: 単位：千円
A4: 項目 | E4: 2020年2月1日～ 2021年1月31日 | F4: 構成比 | G4: 2021年2月1日～2022年1月31日 | H4: 構成比 | I4: 前年比 増加率 | J4: 2022年2月1日～2023年1月31日 | K4: 構成比 | L4: 前年比 増加率 | M4: 増減額 | O4: 特徴／備考
E5: 前々期 | F5: ％ | G5: 前期 | H5: ％ | I5: ％ | J5: 今期 | K5: ％ | L5: ％ | M5: =G5 -> 前期 | N5: =J5 -> 今期
A6: 資産の部 | B6: 流動資産 | C6: 当座資産 | D6: 現金・預金 | F6: =IF(E6=0,"",E6/E$50) | H6: =IF(G6=0,"",G6/G$50) | I6: =IF(E6*G6=0,"",G6/E6) | K6: =IF(J6=0,"",J6/J$50) | L6: =IF(G6*J6=0,"",J6/G6) | M6: =G6-E6 -> 0 | N6: =J6-G6 -> 0
D7: （うち定期預金） | F7: =IF(E7=0,"",E7/E$50) | H7: =IF(G7=0,"",G7/G$50) | I7: =IF(E7*G7=0,"",G7/E7) | K7: =IF(J7=0,"",J7/J$50) | L7: =IF(G7*J7=0,"",J7/G7) | M7: =G7-E7 -> 0 | N7: =J7-G7 -> 0
D8: 受取手形 | F8: =IF(E8=0,"",E8/E$50) | H8: =IF(G8=0,"",G8/G$50) | I8: =IF(E8*G8=0,"",G8/E8) | K8: =IF(J8=0,"",J8/J$50) | L8: =IF(G8*J8=0,"",J8/G8) | M8: =G8-E8 -> 0 | N8: =J8-G8 -> 0
D9: 売掛金 | F9: =IF(E9=0,"",E9/E$50) | H9: =IF(G9=0,"",G9/G$50) | I9: =IF(E9*G9=0,"",G9/E9) | K9: =IF(J9=0,"",J9/J$50) | L9: =IF(G9*J9=0,"",J9/G9) | M9: =G9-E9 -> 0 | N9: =J9-G9 -> 0
F10: =IF(E10=0,"",E10/E$50) | H10: =IF(G10=0,"",G10/G$50) | I10: =IF(E10*G10=0,"",G10/E10) | K10: =IF(J10=0,"",J10/J$50) | L10: =IF(G10*J10=0,"",J10/G10) | M10: =G10-E10 -> 0 | N10: =J10-G10 -> 0
D11: 小計 | E11: =SUM(E6:E10)-E7 -> 0 | F11: =IF(E11=0,"",E11/E$50) | G11: =SUM(G6:G10)-G7 -> 0 | H11: =IF(G11=0,"",G11/G$50) | I11: =IF(E11*G11=0,"",G11/E11) | J11: =SUM(J6:J10)-J7 -> 0 | K11: =IF(J11=0,"",J11/J$50) | L11: =IF(G11*J11=0,"",J11/G11) | M11: =G11-E11 -> 0 | N11: =J11-G11 -> 0
C12: 棚卸資産 | D12: 製品・商品 | E12: 0 | F12: =IF(E12=0,"",E12/E$50) | H12: =IF(G12=0,"",G12/G$50) | I12: =IF(E12*G12=0,"",G12/E12) | K12: =IF(J12=0,"",J12/J$50) | L12: =IF(G12*J12=0,"",J12/G12) | M12: =G12-E12 -> 0 | N12: =J12-G12 -> 0
D13: 原材料 | E13: 0 | F13: =IF(E13=0,"",E13/E$50) | H13: =IF(G13=0,"",G13/G$50) | I13: =IF(E13*G13=0,"",G13/E13) | K13: =IF(J13=0,"",J13/J$50) | L13: =IF(G13*J13=0,"",J13/G13) | M13: =G13-E13 -> 0 | N13: =J13-G13 -> 0
D14: 仕掛品 | E14: 0 | F14: =IF(E14=0,"",E14/E$50) | H14: =IF(G14=0,"",G14/G$50) | I14: =IF(E14*G14=0,"",G14/E14) | K14: =IF(J14=0,"",J14/J$50) | L14: =IF(G14*J14=0,"",J14/G14) | M14: =G14-E14 -> 0 | N14: =J14-G14 -> 0
F15: =IF(E15=0,"",E15/E$50) | H15: =IF(G15=0,"",G15/G$50) | I15: =IF(E15*G15=0,"",G15/E15) | K15: =IF(J15=0,"",J15/J$50) | L15: =IF(G15*J15=0,"",J15/G15) | M15: =G15-E15 -> 0 | N15: =J15-G15 -> 0
D16: 小計 | E16: =SUM(E12:E15) -> 0 | F16: =IF(E16=0,"",E16/E$50) | G16: =SUM(G12:G15) -> 0 | H16: =IF(G16=0,"",G16/G$50) | I16: =IF(E16*G16=0,"",G16/E16) | J16: =SUM(J12:J15) -> 0 | K16: =IF(J16=0,"",J16/J$50) | L16: =IF(G16*J16=0,"",J16/G16) | M16: =G16-E16 -> 0 | N16: =J16-G16 -> 0
C17: その他流動資産 | F17: =IF(E17=0,"",E17/E$50) | H17: =IF(G17=0,"",G17/G$50) | I17: =IF(E17*G17=0,"",G17/E17) | K17: =IF(J17=0,"",J17/J$50) | L17: =IF(G17*J17=0,"",J17/G17) | M17: =G17-E17 -> 0 | N17: =J17-G17 -> 0
F18: =IF(E18=0,"",E18/E$50) | H18: =IF(G18=0,"",G18/G$50) | I18: =IF(E18*G18=0,"",G18/E18) | K18: =IF(J18=0,"",J18/J$50) | L18: =IF(G18*J18=0,"",J18/G18) | M18: =G18-E18 -> 0 | N18: =J18-G18 -> 0
F19: =IF(E19=0,"",E19/E$50) | H19: =IF(G19=0,"",G19/G$50) | I19: =IF(E19*G19=0,"",G19/E19) | K19: =IF(J19=0,"",J19/J$50) | L19: =IF(G19*J19=0,"",J19/G19) | M19: =G19-E19 -> 0 | N19: =J19-G19 -> 0
F20: =IF(E20=0,"",E20/E$50) | H20: =IF(G20=0,"",G20/G$50) | I20: =IF(E20*G20=0,"",G20/E20) | K20: =IF(J20=0,"",J20/J$50) | L20: =IF(G20*J20=0,"",J20/G20) | M20: =G20-E20 -> 0 | N20: =J20-G20 -> 0
F21: =IF(E21=0,"",E21/E$50) | H21: =IF(G21=0,"",G21/G$50) | I21: =IF(E21*G21=0,"",G21/E21) | K21: =IF(J21=0,"",J21/J$50) | L21: =IF(G21*J21=0,"",J21/G21) | M21: =G21-E21 -> 0 | N21: =J21-G21 -> 0
F22: =IF(E22=0,"",E22/E$50) | H22: =IF(G22=0,"",G22/G$50) | I22: =IF(E22*G22=0,"",G22/E22) | K22: =IF(J22=0,"",J22/J$50) | L22: =IF(G22*J22=0,"",J22/G22) | M22: =G22-E22 -> 0 | N22: =J22-G22 -> 0
F23: =IF(E23=0,"",E23/E$50) | H23: =IF(G23=0,"",G23/G$50) | I23: =IF(E23*G23=0,"",G23/E23) | K23: =IF(J23=0,"",J23/J$50) | L23: =IF(G23*J23=0,"",J23/G23) | M23: =G23-E23 -> 0 | N23: =J23-G23 -> 0
F24: =IF(E24=0,"",E24/E$50) | H24: =IF(G24=0,"",G24/G$50) | I24: =IF(E24*G24=0,"",G24/E24) | K24: =IF(J24=0,"",J24/J$50) | L24: =IF(G24*J24=0,"",J24/G24) | M24: =G24-E24 -> 0 | N24: =J24-G24 -> 0
D25: 貸倒引当金（▲） | E25: 0 | F25: =IF(E25=0,"",E25/E$50) | H25: =IF(G25=0,"",G25/G$50) | I25: =IF(E25*G25=0,"",G25/E25) | K25: =IF(J25=0,"",J25/J$50) | L25: =IF(G25*J25=0,"",J25/G25) | M25: =G25-E25 -> 0 | N25: =J25-G25 -> 0
F26: =IF(E26=0,"",E26/E$50) | H26: =IF(G26=0,"",G26/G$50) | I26: =IF(E26*G26=0,"",G26/E26) | K26: =IF(J26=0,"",J26/J$50) | L26: =IF(G26*J26=0,"",J26/G26) | M26: =G26-E26 -> 0 | N26: =J26-G26 -> 0
D27: 小計 | E27: =SUM(E17:E26) -> 0 | F27: =IF(E27=0,"",E27/E$50) | G27: =SUM(G17:G26) -> 0 | H27: =IF(G27=0,"",G27/G$50) | I27: =IF(E27*G27=0,"",G27/E27) | J27: =SUM(J17:J26) -> 0 | K27: =IF(J27=0,"",J27/J$50) | L27: =IF(G27*J27=0,"",J27/G27) | M27: =G27-E27 -> 0 | N27: =J27-G27 -> 0
B28: 流動資産合計 | E28: =E11+E16+E27 -> 0 | F28: =IF(E28=0,"",E28/E$50) | G28: =G11+G16+G27 -> 0 | H28: =IF(G28=0,"",G28/G$50) | I28: =IF(E28*G28=0,"",G28/E28) | J28: =J11+J16+J27 -> 0 | K28: =IF(J28=0,"",J28/J$50) | L28: =IF(G28*J28=0,"",J28/G28) | M28: =G28-E28 -> 0 | N28: =J28-G28 -> 0
B29: 固定資産 | C29: 有形固定資産 | D29: 建物付属設備 | F29: =IF(E29=0,"",E29/E$50) | H29: =IF(G29=0,"",G29/G$50) | I29: =IF(E29*G29=0,"",G29/E29) | K29: =IF(J29=0,"",J29/J$50) | L29: =IF(G29*J29=0,"",J29/G29) | M29: =G29-E29 -> 0 | N29: =J29-G29 -> 0
D30: 構築物 | F30: =IF(E30=0,"",E30/E$50) | H30: =IF(G30=0,"",G30/G$50) | I30: =IF(E30*G30=0,"",G30/E30) | K30: =IF(J30=0,"",J30/J$50) | L30: =IF(G30*J30=0,"",J30/G30) | M30: =G30-E30 -> 0 | N30: =J30-G30 -> 0
D31: 機械装置 | F31: =IF(E31=0,"",E31/E$50) | H31: =IF(G31=0,"",G31/G$50) | I31: =IF(E31*G31=0,"",G31/E31) | K31: =IF(J31=0,"",J31/J$50) | L31: =IF(G31*J31=0,"",J31/G31) | M31: =G31-E31 -> 0 | N31: =J31-G31 -> 0
D32: 車両運搬具 | F32: =IF(E32=0,"",E32/E$50) | H32: =IF(G32=0,"",G32/G$50) | I32: =IF(E32*G32=0,"",G32/E32) | K32: =IF(J32=0,"",J32/J$50) | L32: =IF(G32*J32=0,"",J32/G32) | M32: =G32-E32 -> 0 | N32: =J32-G32 -> 0
D33: 什器・備品 | F33: =IF(E33=0,"",E33/E$50) | H33: =IF(G33=0,"",G33/G$50) | I33: =IF(E33*G33=0,"",G33/E33) | K33: =IF(J33=0,"",J33/J$50) | L33: =IF(G33*J33=0,"",J33/G33) | M33: =G33-E33 -> 0 | N33: =J33-G33 -> 0
D34: 土地 | F34: =IF(E34=0,"",E34/E$50) | H34: =IF(G34=0,"",G34/G$50) | I34: =IF(E34*G34=0,"",G34/E34) | K34: =IF(J34=0,"",J34/J$50) | L34: =IF(G34*J34=0,"",J34/G34) | M34: =G34-E34 -> 0 | N34: =J34-G34 -> 0
D35: 建設仮勘定 | F35: =IF(E35=0,"",E35/E$50) | H35: =IF(G35=0,"",G35/G$50) | I35: =IF(E35*G35=0,"",G35/E35) | K35: =IF(J35=0,"",J35/J$50) | L35: =IF(G35*J35=0,"",J35/G35) | M35: =G35-E35 -> 0 | N35: =J35-G35 -> 0
D36: リース資産 | F36: =IF(E36=0,"",E36/E$50) | H36: =IF(G36=0,"",G36/G$50) | I36: =IF(E36*G36=0,"",G36/E36) | K36: =IF(J36=0,"",J36/J$50) | L36: =IF(G36*J36=0,"",J36/G36) | M36: =G36-E36 -> 0 | N36: =J36-G36 -> 0
D37: 小計 | E37: =SUM(E29:E36) -> 0 | F37: =IF(E37=0,"",E37/E$50) | G37: =SUM(G29:G36) -> 0 | H37: =IF(G37=0,"",G37/G$50) | I37: =IF(E37*G37=0,"",G37/E37) | J37: =SUM(J29:J36) -> 0 | K37: =IF(J37=0,"",J37/J$50) | L37: =IF(G37*J37=0,"",J37/G37) | M37: =G37-E37 -> 0 | N37: =J37-G37 -> 0
C38: 無形固定資産 | F38: =IF(E38=0,"",E38/E$50) | H38: =IF(G38=0,"",G38/G$50) | I38: =IF(E38*G38=0,"",G38/E38) | K38: =IF(J38=0,"",J38/J$50) | L38: =IF(G38*J38=0,"",J38/G38) | M38: =G38-E38 -> 0 | N38: =J38-G38 -> 0
C39: 投資等 | D39: 投資有価証券 | F39: =IF(E39=0,"",E39/E$50) | H39: =IF(G39=0,"",G39/G$50) | I39: =IF(E39*G39=0,"",G39/E39) | K39: =IF(J39=0,"",J39/J$50) | L39: =IF(G39*J39=0,"",J39/G39) | M39: =G39-E39 -> 0 | N39: =J39-G39 -> 0
D40: 出資金 | F40: =IF(E40=0,"",E40/E$50) | H40: =IF(G40=0,"",G40/G$50) | I40: =IF(E40*G40=0,"",G40/E40) | K40: =IF(J40=0,"",J40/J$50) | L40: =IF(G40*J40=0,"",J40/G40) | M40: =G40-E40 -> 0 | N40: =J40-G40 -> 0
...

Sheet 経営分析シート
A1: ='財務諸表（入力）'!D1 -> 0
A3: １．損益分岐点分析
G4: 単位：千円 | J4: 増減率
E5: ='財務諸表（入力）'!$E$5 -> 前々期 | F5: ='財務諸表（入力）'!$G$5 -> 前期 | G5: ='財務諸表（入力）'!$J$5 -> 今期 | H5: 算式 | J5: =F5 -> 前期 | K5: =G5 -> 今期 | AC5: 変動費の内訳
A6: 売上高 | E6: ='財務諸表（入力）'!E129 -> 0 | F6: ='財務諸表（入力）'!G129 -> 0 | G6: ='財務諸表（入力）'!J129 -> 0 | J6: =IF(F6="","",F6/E6) -> #DIV/0! | K6: =IF(G6="","",G6/F6) -> #DIV/0! | AD6: ='財務諸表（入力）'!$E$5 -> 前々期 | AE6: ='財務諸表（入力）'!$G$5 -> 前期 | AF6: ='財務諸表（入力）'!$J$5 -> 今期
A7: 変動費 | E7: ='財務諸表（入力）'!E96+SUMIF('財務諸表（入力）'!$C$97:$C$116,"V",'財務諸表（入力）'!$E$97:$E$116)+'財務諸表（入力）'!E122+'財務諸表（入力）'!E131+'財務諸表（入力）'!E135+SUMIF('財務諸表（入力）'!$C$138:$C$155,"V",'財務諸表（入力）'!$E$138:$E$155)-'財務諸表（入力）'!E121-'財務諸表（入力）'!E133 -> 0 | F7: ='財務諸表（入力）'!G96+SUMIF('財務諸表（入力）'!$C$97:$C$116,"V",'財務諸表（入力）'!$G$97:$G$116)+'財務諸表（入力）'!G122+'財務諸表（入力）'!G131+'財務諸表（入力）'!G135+SUMIF('財務諸表（入力）'!$C$138:$C$155,"V",'財務諸表（入力）'!$G$138:$G$155)-'財務諸表（入力）'!$G121-'財務諸表（入力）'!G133 -> 0 | G7: ='財務諸表（入力）'!J96+SUMIF('財務諸表（入力）'!$C$97:$C$116,"V",'財務諸表（入力）'!$J$97:$J$116)+'財務諸表（入力）'!J122+'財務諸表（入力）'!J131+'財務諸表（入力）'!J135+SUMIF('財務諸表（入力）'!$C$138:$C$155,"V",'財務諸表（入力）'!$J$138:$J$155)-'財務諸表（入力）'!$J121-'財務諸表（入力）'!J133 -> 0 | J7: =IF(F7="","",F7/E7) -> #DIV/0! | K7: =IF(G7="","",G7/F7) -> #DIV/0! | AC7: 材料費 | AD7: ='財務諸表（入力）'!E96 -> 0 | AE7: ='財務諸表（入力）'!G96 -> 0 | AF7: ='財務諸表（入力）'!J96 -> 0
A8: 限界利益 | E8: =E6-E7 -> 0 | F8: =F6-F7 -> 0 | G8: =G6-G7 -> 0 | H8: 売上高-変動費 | J8: =IF(F8="","",F8/E8) -> #DIV/0! | K8: =IF(G8="","",G8/F8) -> #DIV/0! | AC8: 労務費 | AD8: =SUMIF('財務諸表（入力）'!$C$97:$C$100,"V",'財務諸表（入力）'!$E$97:$E$100) -> 0 | AE8: =SUMIF('財務諸表（入力）'!$C$97:$C$100,"V",'財務諸表（入力）'!$G$97:$G$100) -> 0 | AF8: =SUMIF('財務諸表（入力）'!$C$97:$C$100,"V",'財務諸表（入力）'!$J$97:$J$100) -> 0
A9: 限界利益率 | E9: =IF(E8*E6=0,"",E8/E6) | F9: =IF(F8*F6=0,"",F8/F6) | G9: =IF(G8*G6=0,"",G8/G6) | H9: 限界利益÷売上高（％） | J9: =IF(F9="","",F9/E9) | K9: =IF(G9="","",G9/F9) | AC9: 製造原価 | AD9: =SUMIF('財務諸表（入力）'!$C$102:$C$116,"V",'財務諸表（入力）'!$E$102:$E$116) -> 0 | AE9: =SUMIF('財務諸表（入力）'!$C$102:$C$116,"V",'財務諸表（入力）'!$G$102:$G$116) -> 0 | AF9: =SUMIF('財務諸表（入力）'!$C$102:$C$116,"V",'財務諸表（入力）'!$J$102:$J$116) -> 0
A10: 固定費 | E10: =SUMIF('財務諸表（入力）'!$C$97:$C$116,"F",'財務諸表（入力）'!$E$97:$E$116)+SUMIF('財務諸表（入力）'!$C$138:$C$155,"F",'財務諸表（入力）'!$E$138:$E$155)+'財務諸表（入力）'!E165-'財務諸表（入力）'!E162 -> 0 | F10: =SUMIF('財務諸表（入力）'!$C$97:$C$116,"F",'財務諸表（入力）'!$G$97:$G$116)+SUMIF('財務諸表（入力）'!$C$138:$C$155,"F",'財務諸表（入力）'!$G$138:$G$155)+'財務諸表（入力）'!G165-'財務諸表（入力）'!G162 -> 0 | G10: =SUMIF('財務諸表（入力）'!$C$97:$C$116,"F",'財務諸表（入力）'!$J$97:$J$116)+SUMIF('財務諸表（入力）'!$C$138:$C$155,"F",'財務諸表（入力）'!$J$138:$J$155)+'財務諸表（入力）'!J165-'財務諸表（入力）'!J162 -> 0 | J10: =IF(F10="","",F10/E10) -> #DIV/0! | K10: =IF(G10="","",G10/F10) -> #DIV/0! | AC10: 販売管理費 | AD10: =SUMIF('財務諸表（入力）'!$C$138:$C$155,"V",'財務諸表（入力）'!$E$138:$E$155) -> 0 | AE10: =SUMIF('財務諸表（入力）'!$C$138:$C$155,"V",'財務諸表（入力）'!$G$138:$G$155) -> 0 | AF10: =SUMIF('財務諸表（入力）'!$C$138:$C$155,"V",'財務諸表（入力）'!$J$138:$J$155) -> 0
A11: 経常利益 | E11: =E8-E10 -> 0 | F11: =F8-F10 -> 0 | G11: =G8-G10 -> 0 | H11: 限界利益ー固定費 | J11: =IF(F11="","",F11/E11) -> #DIV/0! | K11: =IF(G11="","",G11/F11) -> #DIV/0! | AC11: 期首－期末仕掛品 | AD11: ='財務諸表（入力）'!E122 -> 0 | AE11: ='財務諸表（入力）'!G122 -> 0 | AF11: ='財務諸表（入力）'!J122 -> 0
A12: 損益分岐点売上高 | E12: =IF(E10*E9=0,"",E10/E9) -> #VALUE! | F12: =IF(F10*F9=0,"",F10/F9) -> #VALUE! | G12: =IF(G10*G9=0,"",G10/G9) -> #VALUE! | H12: 固定費÷限界利益率 | J12: =IF(F12="","",F12/E12) -> #VALUE! | K12: =IF(G12="","",G12/F12) -> #VALUE! | AC12: 商品仕入高 | AD12: ='財務諸表（入力）'!E131 -> 0 | AE12: ='財務諸表（入力）'!G131 -> 0 | AF12: ='財務諸表（入力）'!J131 -> 0
A13: 損益分岐点比率 | E13: =IF(E12*E6=0,"",E12/E6) -> #VALUE! | F13: =IF(F12*F6=0,"",F12/F6) -> #VALUE! | G13: =IF(G12*G6=0,"",G12/G6) -> #VALUE! | H13: 損益分岐点売上高÷売上高 | J13: =IF(F13="","",F13/E13) -> #VALUE! | K13: =IF(G13="","",G13/F13) -> #VALUE! | AC13: 期首－期末製品棚卸高 | AD13: ='財務諸表（入力）'!E135 -> 0 | AE13: ='財務諸表（入力）'!G135 -> 0 | AF13: ='財務諸表（入力）'!J135 -> 0
A14: 安全余裕率 | E14: =IF(E13=0,"",1-E13) -> #VALUE! | F14: =IF(F13=0,"",1-F13) -> #VALUE! | G14: =IF(G13=0,"",1-G13) -> #VALUE! | H14: 100%-損益分岐点比率 | J14: =IF(F14="","",F14/E14) -> #VALUE! | K14: =IF(G14="","",G14/F14) -> #VALUE! | AC14: 他勘定振替高 | AD14: ='財務諸表（入力）'!E121 -> 0 | AE14: ='財務諸表（入力）'!G121 -> 0 | AF14: ='財務諸表（入力）'!J121 -> 0
A15: 変動費比率 | E15: =IF(E7*E6=0,"",E7/E6) | F15: =IF(F7*F6=0,"",F7/F6) | G15: =IF(G7*G6=0,"",G7/G6) | AC15: 合計 | AD15: =SUM(AD7:AD13)-AD14 -> 0 | AE15: =SUM(AE7:AE13)-AE14 -> 0 | AF15: =SUM(AF7:AF13)-AF14 -> 0
A16: 固定費比率 | E16: =IF(E10*E6=0,"",E10/E6) | F16: =IF(F10*F6=0,"",F10/F6) | G16: =IF(G10*G6=0,"",G10/G6)
D17: 照合（０でOK) | E17: ='財務諸表（入力）'!E166-E11 -> 0 | F17: ='財務諸表（入力）'!G166-F11 -> 0 | G17: ='財務諸表（入力）'!J166-G11 -> 0
A18: ◆変動費（Ｖ）・固定費（Ｆ）の分類は製造原価報告書・損益計算書を参照
A22: ２．バランスシート分析（貸借対照表の構成比率）
A24: （１）ＢＳの資産・負債・純資産構成
E25: ='財務諸表（入力）'!$E$5 -> 前々期 | F25: ='財務諸表（入力）'!$G$5 -> 前期 | G25: ='財務諸表（入力）'!$J$5 -> 今期
A26: 流動資産 | E26: ='財務諸表（入力）'!F28 | F26: =IF('財務諸表（入力）'!H28=0,"",'財務諸表（入力）'!H28) | G26: =IF('財務諸表（入力）'!K28=0,"",'財務諸表（入力）'!K28)
A27: 固定資産 | E27: ='財務諸表（入力）'!F49 | F27: =IF('財務諸表（入力）'!H49=0,"",'財務諸表（入力）'!H49) | G27: =IF('財務諸表（入力）'!K49=0,"",'財務諸表（入力）'!K49)
A28: 流動負債 | E28: ='財務諸表（入力）'!F61 | F28: =IF('財務諸表（入力）'!H61=0,"",'財務諸表（入力）'!H61) | G28: =IF('財務諸表（入力）'!K61=0,"",'財務諸表（入力）'!K61)
A29: 固定負債 | E29: ='財務諸表（入力）'!F69 | F29: =IF('財務諸表（入力）'!H69=0,"",'財務諸表（入力）'!H69) | G29: =IF('財務諸表（入力）'!K69=0,"",'財務諸表（入力）'!K69)
A30: 純資産 | E30: ='財務諸表（入力）'!F79 | F30: =IF('財務諸表（入力）'!H79=0,"",'財務諸表（入力）'!H79) | G30: =IF('財務諸表（入力）'!K79=0,"",'財務諸表（入力）'!K79)
A31: 総資本 | E31: ='財務諸表（入力）'!F80 -> #VALUE! | F31: =IF('財務諸表（入力）'!H80=0,"",'財務諸表（入力）'!H80) -> #VALUE! | G31: =IF('財務諸表（入力）'!K80=0,"",'財務諸表（入力）'!K80) -> #VALUE!
A33: （２）売上と主要ＢＳ科目の推移
E34: ='財務諸表（入力）'!$E$5 -> 前々期 | F34: ='財務諸表（入力）'!$G$5 -> 前期 | G34: ='財務諸表（入力）'!$J$5 -> 今期
A35: 売上高 | E35: =IF('財務諸表（入力）'!E129="","",'財務諸表（入力）'!E129/'財務諸表（入力）'!$E$129) | F35: =IF('財務諸表（入力）'!G129="","",'財務諸表（入力）'!G129/'財務諸表（入力）'!$E$129) | G35: =IF('財務諸表（入力）'!J129="","",'財務諸表（入力）'!J129/'財務諸表（入力）'!$E$129)
A36: 現預金 | E36: =IF('財務諸表（入力）'!E6="","",'財務諸表（入力）'!E6/'財務諸表（入力）'!$E$6) | F36: =IF('財務諸表（入力）'!G6="","",'財務諸表（入力）'!G6/'財務諸表（入力）'!$E$6) | G36: =IF('財務諸表（入力）'!J6="","",'財務諸表（入力）'!J6/'財務諸表（入力）'!$E$6)
A37: 売上債権 | E37: =IF(('財務諸表（入力）'!E9+'財務諸表（入力）'!E8+'財務諸表（入力）'!E83+'財務諸表（入力）'!E84)="","",('財務諸表（入力）'!E9+'財務諸表（入力）'!E8+'財務諸表（入力）'!E83+'財務諸表（入力）'!E84)/('財務諸表（入力）'!$E$9+'財務諸表（入力）'!$E$8+'財務諸表（入力）'!$E$83+'財務諸表（入力）'!$E$84)) -> #DIV/0! | F37: =IF(('財務諸表（入力）'!G9+'財務諸表（入力）'!G8+'財務諸表（入力）'!G83+'財務諸表（入力）'!G84)="","",('財務諸表（入力）'!G9+'財務諸表（入力）'!G8+'財務諸表（入力）'!G83+'財務諸表（入力）'!G84)/('財務諸表（入力）'!$E$9+'財務諸表（入力）'!$E$8+'財務諸表（入力）'!$E$83+'財務諸表（入力）'!$E$84)) -> #DIV/0! | G37: =IF(('財務諸表（入力）'!J9+'財務諸表（入力）'!J8+'財務諸表（入力）'!J83+'財務諸表（入力）'!J84)="","",('財務諸表（入力）'!J9+'財務諸表（入力）'!J8+'財務諸表（入力）'!J83+'財務諸表（入力）'!J84)/('財務諸表（入力）'!$E$9+'財務諸表（入力）'!$E$8+'財務諸表（入力）'!$E$83+'財務諸表（入力）'!$E$84)) -> #DIV/0!
A38: 棚卸資産 | E38: =IF('財務諸表（入力）'!E16="","",('財務諸表（入力）'!E16/'財務諸表（入力）'!$E$16)) -> #DIV/0! | F38: =IF('財務諸表（入力）'!G16="","",('財務諸表（入力）'!G16/'財務諸表（入力）'!$E$16)) -> #DIV/0! | G38: =IF('財務諸表（入力）'!J16="","",('財務諸表（入力）'!J16/'財務諸表（入力）'!$E$16)) -> #DIV/0!
A39: 買入債務 | E39: =IF(('財務諸表（入力）'!E51+'財務諸表（入力）'!E52+'財務諸表（入力）'!E84)="","",(('財務諸表（入力）'!E51+'財務諸表（入力）'!E52+'財務諸表（入力）'!E84)/('財務諸表（入力）'!$E$51+'財務諸表（入力）'!$E$52+'財務諸表（入力）'!$E$84))) -> #DIV/0! | F39: =IF(('財務諸表（入力）'!G51+'財務諸表（入力）'!G52+'財務諸表（入力）'!G84)="","",(('財務諸表（入力）'!G51+'財務諸表（入力）'!G52+'財務諸表（入力）'!G84)/('財務諸表（入力）'!$E$51+'財務諸表（入力）'!$E$52+'財務諸表（入力）'!$E$84))) -> #DIV/0! | G39: =IF(('財務諸表（入力）'!J51+'財務諸表（入力）'!J52+'財務諸表（入力）'!J84)="","",(('財務諸表（入力）'!J51+'財務諸表（入力）'!J52+'財務諸表（入力）'!J84)/('財務諸表（入力）'!$E$51+'財務諸表（入力）'!$E$52+'財務諸表（入力）'!$E$84))) -> #DIV/0!
A40: 有形固定資産 | E40: =IF('財務諸表（入力）'!E37="","",('財務諸表（入力）'!E37/'財務諸表（入力）'!$E$37)) -> #DIV/0! | F40: =IF('財務諸表（入力）'!G37="","",('財務諸表（入力）'!G37/'財務諸表（入力）'!$E$37)) -> #DIV/0! | G40: =IF('財務諸表（入力）'!J37="","",('財務諸表（入力）'!J37/'財務諸表（入力）'!$E$37)) -> #DIV/0!
A41: 投資等 | E41: =IF('財務諸表（入力）'!E47="","",('財務諸表（入力）'!E47/'財務諸表（入力）'!$E$47)) -> #DIV/0! | F41: =IF('財務諸表（入力）'!G47="","",('財務諸表（入力）'!G47/'財務諸表（入力）'!$E$47)) -> #DIV/0! | G41: =IF('財務諸表（入力）'!J47="","",('財務諸表（入力）'!J47/'財務諸表（入力）'!$E$47)) -> #DIV/0!
A42: 借入金 | E42: =IF(('財務諸表（入力）'!E53+'財務諸表（入力）'!E62+'財務諸表（入力）'!E63+'財務諸表（入力）'!E83)="","",('財務諸表（入力）'!E53+'財務諸表（入力）'!E62+'財務諸表（入力）'!E63+'財務諸表（入力）'!E83)/('財務諸表（入力）'!$E$53+'財務諸表（入力）'!$E$62+'財務諸表（入力）'!$E$63+'財務諸表（入力）'!$E$83)) -> #DIV/0! | F42: =IF(('財務諸表（入力）'!G53+'財務諸表（入力）'!G62+'財務諸表（入力）'!G63+'財務諸表（入力）'!G83)="","",('財務諸表（入力）'!G53+'財務諸表（入力）'!G62+'財務諸表（入力）'!G63+'財務諸表（入力）'!G83)/('財務諸表（入力）'!$E$53+'財務諸表（入力）'!$E$62+'財務諸表（入力）'!$E$63+'財務諸表（入力）'!$E$83)) -> #DIV/0! | G42: =IF(('財務諸表（入力）'!J53+'財務諸表（入力）'!J62+'財務諸表（入力）'!J63+'財務諸表（入力）'!J83)="","",('財務諸表（入力）'!J53+'財務諸表（入力）'!J62+'財務諸表（入力）'!J63+'財務諸表（入力）'!J83)/('財務諸表（入力）'!$E$53+'財務諸表（入力）'!$E$62+'財務諸表（入力）'!$E$63+'財務諸表（入力）'!$E$83)) -> #DIV/0!
A43: 純資産 | E43: =IF('財務諸表（入力）'!E79="","",('財務諸表（入力）'!E79/'財務諸表（入力）'!$E$79)) -> #DIV/0! | F43: =IF('財務諸表（入力）'!G79="","",('財務諸表（入力）'!G79/'財務諸表（入力）'!$E$79)) -> #DIV/0! | G43: =IF('財務諸表（入力）'!J79="","",('財務諸表（入力）'!J79/'財務諸表（入力）'!$E$79)) -> #DIV/0!
A44: =CONCATENATE("（",E34,"の各科目の数値を１００とした場合の",F34,"及び",G34,"の推移）") -> （前々期の各科目の数値を１００とした場合の前期及び今期の推移）
A49: ３．運転資金の増減分析
A51: （１）回転期間の変化
...

Sheet 資金運用表
A1: ='財務諸表（入力）'!D1 -> 0 | S1: ='財務諸表（入力）'!A1 -> 企業名 : | U1: ='財務諸表（入力）'!D1 -> 0 | W1: ＊１ 固定資金は固定資産の増減、固定負債、資本の増減
A3: =CONCATENATE("■ ",F41," 資金運用表分析") -> ■ 前期 資金運用表分析
I5: 単位：千円 | S5: ='財務諸表（入力）'!J5 -> 今期 | W5: ＊２ 運転資金は現預金を除く流動資産の増減、短期借入金、割引手形を除く流動負債の増減
D6: 資金の運用 | G6: 資金の調達
A7: 固定資金 | D7: 法人税等支払い | F7: =L121 -> 0 | G7: 税引前当期利益① | I7: =M123 -> 0
D8: 配当金支払い | F8: =L119 -> 0 | G8: 減価償却費等② | I8: =M116 -> 0
D9: 役員賞与支払い | F9: =L120 -> 0 | G9: 増資等 | I9: =(M106+M107+M108)-(L106+L107+L108)+(M112+M113)-(L112+L113) -> 0
D10: 有形固定資産増加 | F10: =L72 -> 0 | G10: 有形固定資産減少 | I10: =M72 -> 0
D11: 長期借入金・社債の減少 | F11: =L97+L101 -> 0 | G11: 長期借入金・社債の増加 | I11: =M97+M101 -> 0
D12: 投資等の増加 | F12: =IF(SUM(L74:L81)>SUM(M74:M81),SUM(L74:L81)-SUM(M74:M81),0) -> 0 | G12: 投資等の減少 | I12: =IF(SUM(L74:L81)<SUM(M74:M81),SUM(M74:M81)-SUM(L74:L81),0) -> 0
D13: 無形・繰延資産増 | F13: =L73+L83 -> 0 | G13: 無形・繰延資産減 | I13: =M73+M83 -> 0
D14: 借入以外の固定負債減 | F14: =IF((SUM(L98:L103)-L101)-(SUM(M98:M103)-M101)>0,(SUM(L98:L103)-L101)-(SUM(M98:M103)-M101),0) -> 0 | G14: 借入以外の固定負債増 | I14: =IF((SUM(L98:L103)-L101)-(SUM(M98:M103)-M101)<0,(SUM(M98:M103)-M101)-(SUM(L98:L103)-L101),0) -> 0
D15: 資金の余剰 | F15: =L125 -> 0 | G15: 資金の不足 | I15: =M125 -> 0
D16: 合計 | F16: =SUM(F7:F15) -> 0 | G16: 合計 | I16: =SUM(I7:I15) -> 0
D17: 照合（０でOK) | F17: =F16-I16 -> 0 | G17: ＣＦ（①＋②） | I17: =I7+I8 -> 0
A19: 運転資金 | D19: 売上債権の増加 | F19: =IF(N43+N44-O43-O44>0,N43+N44-O43-O44,0) -> 0 | G19: 買入債務の増加 | I19: =IF(N86+N87-O86-O87<0,O86+O87-N86-N87,0) -> 0
D20: 棚卸資産の増加 | F20: =N51 -> 0 | G20: 貸倒引当増加 | I20: =IF(N57+N79-O57-O79<0,O57+O79-N57-N79,0) -> 0
D21: その他流動資産増 | F21: =IF(SUM(N52,N53,N54,N55,N56,N58,N59,N60,N61)-SUM(O52,O53,O54,O55,O56,O58,O59,O60,O61)>0,SUM(N52,N53,N54,N55,N56,N58,N59,N60,N61)-SUM(O52,O53,O54,O55,O56,O58,O59,O60,O61),0) -> 0 | G21: その他流動負債増 | I21: =IF(SUM(N89:N95)-SUM(O89:O95)<0,SUM(O89:O95)-SUM(N89:N95),0) -> 0
D22: 買入債務減少 | F22: =IF(N86+N87-O86-O87>0,N86+N87-O86-O87,0) -> 0 | G22: 売上債権の減少 | I22: =IF(N43+N44-O43-O44<0,O43+O44-N43-N44,0) -> 0
D23: その他流動負債減 | F23: =IF(SUM(N89:N95)-SUM(O89:O95)>0,SUM(N89:N95)-SUM(O89:O95),0) -> 0 | G23: 棚卸資産の減少 | I23: =O51 -> 0
D24: 貸倒引当減少 | F24: =IF(N57+N79-O57-O79>0,N57+N79-O57-O79,0) -> 0 | G24: その他流動資産減 | I24: =IF(SUM(N52,N53,N54,N55,N56,N58,N59,N60,N61)-SUM(O52,O53,O54,O55,O56,O58,O59,O60,O61)<0,SUM(O52,O53,O54,O55,O56,O58,O59,O60,O61)-SUM(N52,N53,N54,N55,N56,N58,N59,N60,N61),0) -> 0
D25: 有価証券等の増加 | F25: =N45 -> 0 | G25: 有価証券等の減少 | I25: =O45 -> 0
D26: 資金の余剰 | F26: =N125 -> 0 | G26: 資金の不足 | I26: =O125 -> 0
D27: 合計 | F27: =SUM(F19:F26) -> 0 | G27: 合計 | I27: =SUM(I19:I26) -> 0
D28: 照合（０でOK) | F28: =I27-F27 -> 0
A30: 財務資金 | D30: 現預金増加 | F30: =P42 -> 0 | G30: 短期借入金増加 | I30: =Q88 -> 0
D31: 短期借入金減少 | F31: =P88 -> 0 | G31: 割引手形等増加 | I31: =Q117 -> 0
D32: 割引手形等減少 | F32: =P117 -> 0 | G32: 現預金減少 | I32: =Q42 -> 0
D33: 固定資金の不足 | F33: =I15 -> 0 | G33: 固定資金の余剰 | I33: =F15 -> 0
D34: 運転資金の不足 | F34: =I26 -> 0 | G34: 運転資金の余剰 | I34: =F26 -> 0
D35: 合計 | F35: =SUM(F30:F34) -> 0 | G35: 合計 | I35: =SUM(I30:I34) -> 0
D36: 照合（０でOK) | F36: =I35-F35 -> 0
D37: 精算表と照合 | F37: =F35-P126 -> 0 | I37: =I35-Q126 -> 0
A39: 【精算表】
A40: ='財務諸表（入力）'!A4 -> 項目 | E40: ='財務諸表（入力）'!E4 -> 2020年2月1日～ 2021年1月31日 | F40: ='財務諸表（入力）'!G4 -> 2021年2月1日～2022年1月31日 | G40: 増減 | H40: 増減仕訳 | J40: 修正 | L40: 固定資金 | N40: 運転資金 | P40: 財務資金
E41: ='財務諸表（入力）'!E5 -> 前々期 | F41: ='財務諸表（入力）'!G5 -> 前期 | H41: 借方 | I41: 貸方 | J41: 借方 | K41: 貸方 | L41: 運用 | M41: 調達 | N41: 運用 | O41: 調達 | P41: 運用 | Q41: 調達
A42: 資産の部 | B42: 流動資産 | C42: 当座資産 | D42: ='財務諸表（入力）'!D6 -> 現金・預金 | E42: ='財務諸表（入力）'!E6 -> 0 | F42: ='財務諸表（入力）'!G6 -> 0 | G42: =F42-E42 -> 0 | H42: =IF(G42>1,SUM(G42:G42),0) -> 0 | I42: =IF(G42<1,SUM(G42:G42)*-1,0) -> 0 | N42: - | O42: - | P42: =H42 -> 0 | Q42: =I42 -> 0
D43: ='財務諸表（入力）'!D9 -> 売掛金 | E43: ='財務諸表（入力）'!E9 -> 0 | F43: ='財務諸表（入力）'!G9 -> 0 | G43: =F43-E43 -> 0 | H43: =IF(G43>1,SUM(G43:G43),0) -> 0 | I43: =IF(G43<1,SUM(G43:G43)*-1,0) -> 0 | N43: =H43 -> 0 | O43: =I43 -> 0
D44: ='財務諸表（入力）'!D8 -> 受取手形 | E44: ='財務諸表（入力）'!E8 -> 0 | F44: ='財務諸表（入力）'!G8 -> 0 | G44: =F44-E44 -> 0 | H44: =IF(G44>1,SUM(G44:G44),0) -> 0 | I44: =IF(G44<1,SUM(G44:G44)*-1,0) -> 0 | J44: =K117 -> 0 | K44: =J117 -> 0 | N44: =H44+J44 -> 0 | O44: =I44+K44 -> 0
D45: ='財務諸表（入力）'!D10 -> 0 | E45: ='財務諸表（入力）'!E10 -> 0 | F45: ='財務諸表（入力）'!G10 -> 0 | G45: =F45-E45 -> 0 | H45: =IF(G45>1,SUM(G45:G45),0) -> 0 | I45: =IF(G45<1,SUM(G45:G45)*-1,0) -> 0 | N45: =H45 -> 0 | O45: =I45 -> 0
...

Sheet 資金移動表
A1: ='財務諸表（入力）'!D1 -> 0
A3: ■ 資金移動表分析
A5: ='財務諸表（入力）'!G5 -> 前期 | I5: ='財務諸表（入力）'!J5 -> 今期
A7: 経常収支 | B7: 支出 | E7: 収入 | I7: 経常収支 | J7: 支出 | M7: 収入
B8: 当期売上原価 | C8: の支出 | D8: ='財務諸表（入力）'!G136 -> 0 | E8: 当期売上高 | F8: の収入 | G8: ='財務諸表（入力）'!G129 -> 0 | J8: 当期売上原価 | K8: の支出 | L8: ='財務諸表（入力）'!J136 -> 0 | M8: 当期売上高 | N8: の収入 | O8: ='財務諸表（入力）'!J129 -> 0
B9: 棚卸資産小計 | C9: の増加 | D9: ='財務諸表（入力）'!M16 -> 0 | E9: ='財務諸表（入力）'!D54 -> 未払金 | F9: の増加 | G9: ='財務諸表（入力）'!M54 -> 0 | J9: 棚卸資産小計 | K9: の増加 | L9: ='財務諸表（入力）'!N16 -> 0 | M9: ='財務諸表（入力）'!D54 -> 未払金 | N9: の増加 | O9: ='財務諸表（入力）'!N54 -> 0
B10: ='財務諸表（入力）'!D17 -> 0 | C10: の増加 | D10: ='財務諸表（入力）'!M17 -> 0 | E10: ='財務諸表（入力）'!D55 -> 未払費用 | F10: の増加 | G10: ='財務諸表（入力）'!M55 -> 0 | J10: ='財務諸表（入力）'!D17 -> 0 | K10: の増加 | L10: ='財務諸表（入力）'!N17 -> 0 | M10: ='財務諸表（入力）'!D55 -> 未払費用 | N10: の増加 | O10: ='財務諸表（入力）'!N55 -> 0
B11: ='財務諸表（入力）'!D18 -> 0 | C11: の増加 | D11: ='財務諸表（入力）'!M18 -> 0 | E11: ='財務諸表（入力）'!D56 -> 前受金 | F11: の増加 | G11: ='財務諸表（入力）'!M56 -> 0 | J11: ='財務諸表（入力）'!D18 -> 0 | K11: の増加 | L11: ='財務諸表（入力）'!N18 -> 0 | M11: ='財務諸表（入力）'!D56 -> 前受金 | N11: の増加 | O11: ='財務諸表（入力）'!N56 -> 0
B12: ='財務諸表（入力）'!D19 -> 0 | C12: の増加 | D12: ='財務諸表（入力）'!M19 -> 0 | E12: ='財務諸表（入力）'!D57 -> 預り金 | F12: の増加 | G12: ='財務諸表（入力）'!M57 -> 0 | J12: ='財務諸表（入力）'!D19 -> 0 | K12: の増加 | L12: ='財務諸表（入力）'!N19 -> 0 | M12: ='財務諸表（入力）'!D57 -> 預り金 | N12: の増加 | O12: ='財務諸表（入力）'!N57 -> 0
B13: ='財務諸表（入力）'!D20 -> 0 | C13: の増加 | D13: ='財務諸表（入力）'!M20 -> 0 | E13: ='財務諸表（入力）'!D60 -> 預り保証金他 | F13: の増加 | G13: ='財務諸表（入力）'!M60 -> 0 | J13: ='財務諸表（入力）'!D20 -> 0 | K13: の増加 | L13: ='財務諸表（入力）'!N20 -> 0 | M13: ='財務諸表（入力）'!D60 -> 預り保証金他 | N13: の増加 | O13: ='財務諸表（入力）'!N60 -> 0
B14: ='財務諸表（入力）'!D21 -> 0 | C14: の増加 | D14: ='財務諸表（入力）'!M21 -> 0 | J14: ='財務諸表（入力）'!D21 -> 0 | K14: の増加 | L14: ='財務諸表（入力）'!N21 -> 0
B15: ='財務諸表（入力）'!D22 -> 0 | C15: の増加 | D15: ='財務諸表（入力）'!M22 -> 0 | E15: 貸倒引当金 | F15: の増加 | G15: =('財務諸表（入力）'!M25+'財務諸表（入力）'!M45)*-1 -> 0 | J15: ='財務諸表（入力）'!D22 -> 0 | K15: の増加 | L15: ='財務諸表（入力）'!N22 -> 0 | M15: 貸倒引当金 | N15: の増加 | O15: =('財務諸表（入力）'!N25+'財務諸表（入力）'!N45)*-1 -> 0
B16: ='財務諸表（入力）'!D23 -> 0 | C16: の増加 | D16: ='財務諸表（入力）'!M23 -> 0 | J16: ='財務諸表（入力）'!D23 -> 0 | K16: の増加 | L16: ='財務諸表（入力）'!N23 -> 0
B17: ='財務諸表（入力）'!D24 -> 0 | C17: の増加 | D17: ='財務諸表（入力）'!M24 -> 0 | E17: 売上債権 | F17: の減少 | G17: =('財務諸表（入力）'!M9+'財務諸表（入力）'!M8+'財務諸表（入力）'!M83+'財務諸表（入力）'!M84)*-1 -> 0 | J17: ='財務諸表（入力）'!D24 -> 0 | K17: の増加 | L17: ='財務諸表（入力）'!N24 -> 0 | M17: 売上債権 | N17: の減少 | O17: =('財務諸表（入力）'!N9+'財務諸表（入力）'!N8+'財務諸表（入力）'!N83+'財務諸表（入力）'!N84)*-1 -> 0
B18: ='財務諸表（入力）'!D26 -> 0 | C18: の増加 | D18: ='財務諸表（入力）'!M26 -> 0 | J18: ='財務諸表（入力）'!D26 -> 0 | K18: の増加 | L18: ='財務諸表（入力）'!N26 -> 0
B19: ='財務諸表（入力）'!D10 -> 0 | C19: の増加 | D19: ='財務諸表（入力）'!M10 -> 0 | J19: ='財務諸表（入力）'!D10 -> 0 | K19: の増加 | L19: ='財務諸表（入力）'!N10 -> 0
B20: 販売管理費 | C20: の支出 | D20: ='財務諸表（入力）'!G156 -> 0 | J20: 販売管理費 | K20: の支出 | L20: ='財務諸表（入力）'!J156 -> 0
B21: 買入債務 | C21: の減少 | D21: =('財務諸表（入力）'!M51+'財務諸表（入力）'!M52)*-1 -> 0 | J21: 買入債務 | K21: の減少 | L21: =('財務諸表（入力）'!N51+'財務諸表（入力）'!N52)*-1 -> 0
B22: 減価償却費 | C22: の支出（▲要因） | D22: =('財務諸表（入力）'!G102+'財務諸表（入力）'!G142)*-1 -> 0 | J22: 減価償却費 | K22: の支出（▲要因） | L22: =('財務諸表（入力）'!J102+'財務諸表（入力）'!J142)*-1 -> 0
B23: 営業支出計 | D23: =SUM(D8:D20)+D21+D22 -> 0 | E23: 営業収入計 | G23: =SUM(G8:G15)+G17 -> 0 | J23: 営業支出計 | L23: =SUM(L8:L20)+L21+L22 -> 0 | M23: 営業収入計 | O23: =SUM(O8:O15)+O17 -> 0
B24: 支払利息割引料 | C24: の支出 | D24: ='財務諸表（入力）'!G163 -> 0 | E24: 営業外収益 | F24: の収入 | G24: ='財務諸表（入力）'!G162 -> 0 | J24: 支払利息割引料 | K24: の支出 | L24: ='財務諸表（入力）'!J163 -> 0 | M24: 営業外収益 | N24: の収入 | O24: ='財務諸表（入力）'!J162 -> 0
B25: ='財務諸表（入力）'!D164 -> その他 | C25: の支出 | D25: ='財務諸表（入力）'!G164 -> 0 | J25: ='財務諸表（入力）'!D164 -> その他 | K25: の支出 | L25: ='財務諸表（入力）'!J164 -> 0
B26: 営業外支出計 | D26: =SUM(D24:D25) -> 0 | E26: 営業外収入計 | G26: =SUM(G24:G25) -> 0 | J26: 営業外支出計 | L26: =SUM(L24:L25) -> 0 | M26: 営業外収入計 | O26: =SUM(O24:O25) -> 0
B27: 経常支出計 | D27: =D23+D26 -> 0 | E27: 経常収入計 | G27: =G23+G26 -> 0 | J27: 経常支出計 | L27: =L23+L26 -> 0 | M27: 経常収入計 | O27: =O23+O26 -> 0
B28: 経常収入超過 | D28: =IF(D23+D26-G23-G26<0,G23+G26-D23-D26,0) -> 0 | E28: 経常支出の超過 | G28: =IF(D23+D26-G23-G26>0,D23+D26-G23-G26,0) -> 0 | J28: 経常収入超過 | L28: =IF(L23+L26-O23-O26<0,O23+O26-L23-L26,0) -> 0 | M28: 経常支出の超過 | O28: =IF(L23+L26-O23-O26>0,L23+L26-O23-O26,0) -> 0
B29: 合計 | D29: =D23+D26+D28 -> 0 | E29: 合計 | G29: =G23+G26+G28 -> 0 | J29: 合計 | L29: =L23+L26+L28 -> 0 | M29: 合計 | O29: =O23+O26+O28 -> 0
E30: 照合（０でOK) | G30: =G29-D29 -> 0 | M30: 照合（０でOK) | O30: =O29-L29 -> 0
D32: 経常収支比率 （経常収入÷経常支出） | G32: =G27/D27 -> #DIV/0! | L32: 経常収支比率 （経常収入÷経常支出） | O32: =O27/L27 -> #DIV/0!
A34: 固定収支 | B34: 支出 | E34: 収入 | I34: 固定収支 | J34: 支出 | M34: 収入
B35: 配当金 | C35: の支出 | D35: ='財務諸表（入力）'!G173 -> 0 | E35: 特別利益 | F35: の収入 | G35: ='財務諸表（入力）'!G167 -> 0 | J35: 配当金 | K35: の支出 | L35: ='財務諸表（入力）'!J173 -> 0 | M35: 特別利益 | N35: の収入 | O35: ='財務諸表（入力）'!J167 -> 0
B36: 役員賞与 | C36: の支出 | D36: ='財務諸表（入力）'!G174 -> 0 | E36: 増資 | F36: の収入 | G36: =資金運用表!I9 -> 0 | J36: 役員賞与 | K36: の支出 | L36: ='財務諸表（入力）'!J174 -> 0 | M36: 増資 | N36: の収入 | O36: =資金運用表!I137 -> 0
B37: 利益処分支出計 | D37: =SUM(D35:D36) -> 0 | E37: ='財務諸表（入力）'!D65 -> リース債務 | F37: の増加 | G37: ='財務諸表（入力）'!M65 -> 0 | J37: 利益処分支出計 | L37: =SUM(L35:L36) -> 0 | M37: ='財務諸表（入力）'!D65 -> リース債務 | N37: の増加 | O37: ='財務諸表（入力）'!N65 -> 0
B38: 法人税等 | C38: の支出 | D38: ='財務諸表（入力）'!G170 -> 0 | E38: ='財務諸表（入力）'!D66 -> 0 | F38: の増加 | G38: ='財務諸表（入力）'!M66 -> 0 | J38: 法人税等 | K38: の支出 | L38: ='財務諸表（入力）'!J170 -> 0 | M38: ='財務諸表（入力）'!D66 -> 0 | N38: の増加 | O38: ='財務諸表（入力）'!N66 -> 0
B39: 未払法人税等 | C39: の減少 | D39: ='財務諸表（入力）'!M58 -> 0 | E39: ='財務諸表（入力）'!D67 -> 0 | F39: の増加 | G39: ='財務諸表（入力）'!M67 -> 0 | J39: 未払法人税等 | K39: の減少 | L39: ='財務諸表（入力）'!N58 -> 0 | M39: ='財務諸表（入力）'!D67 -> 0 | N39: の増加 | O39: ='財務諸表（入力）'!N67 -> 0
B40: 未払消費税 | C40: の減少 | D40: ='財務諸表（入力）'!M59 -> 0 | E40: ='財務諸表（入力）'!D68 -> 0 | F40: の増加 | G40: ='財務諸表（入力）'!M68 -> 0 | J40: 未払消費税 | K40: の減少 | L40: ='財務諸表（入力）'!N59 -> 0 | M40: ='財務諸表（入力）'!D68 -> 0 | N40: の増加 | O40: ='財務諸表（入力）'!N68 -> 0
B41: 税金支出計 | D41: =D38-D39-D40 -> 0 | E41: 特別収入 | G41: =SUM(G35:G40) -> 0 | J41: 税金支出計 | L41: =L38-L39-L40 -> 0 | M41: 特別収入 | O41: =SUM(O35:O40) -> 0
B42: 有形固定資産 | C42: の増加 | D42: ='財務諸表（入力）'!M37+'財務諸表（入力）'!G182 -> 0 | J42: 有形固定資産 | K42: の増加 | L42: ='財務諸表（入力）'!N37+'財務諸表（入力）'!J182 -> 0
B43: 投資等 | C43: の増加 | D43: =SUM('財務諸表（入力）'!M39:M44)+'財務諸表（入力）'!M46 -> 0 | J43: 投資等 | K43: の増加 | L43: =SUM('財務諸表（入力）'!N39:N44)+'財務諸表（入力）'!N46 -> 0
B44: 無形固定資産 | C44: の増加 | D44: ='財務諸表（入力）'!M38 -> 0 | J44: 無形固定資産 | K44: の増加 | L44: ='財務諸表（入力）'!N38 -> 0
B45: 繰延資産 | C45: の増加 | D45: ='財務諸表（入力）'!M48 -> 0 | J45: 繰延資産 | K45: の増加 | L45: ='財務諸表（入力）'!N48 -> 0
...

Sheet 変動PL＆BEP
A1: ■ 変動ＰＬによる将来シミュレーション
P2: 単位：千円
E3: 直近期実績 | G3: 計画
G4: 計画1期 | I4: 計画2期 | K4: 計画3期 | M4: 計画4期 | O4: 計画5期
E5: ='財務諸表（入力）'!J4 -> 2022年2月1日～2023年1月31日 | F5: 売上比 | H5: 売上比 | J5: 売上比 | L5: 売上比 | N5: 売上比 | P5: 売上比
A6: 売上高 | E6: ='財務諸表（入力）'!J129 -> 0 | F6: =IF(E6=0,"",E6/E$6) | G6: =IF(E6="","",E6*(1+G51)) -> 0 | H6: =IF(G6="","",G6/G$6) -> #DIV/0! | I6: =IF(G6="","",G6*(1+I51)) -> 0 | J6: =IF(I6="","",I6/I$6) -> #DIV/0! | K6: =IF(I6="","",I6*(1+K51)) -> 0 | L6: =IF(K6="","",K6/K$6) -> #DIV/0! | M6: =IF(K6="","",K6*(1+M51)) -> 0 | N6: =IF(M6="","",M6/M$6) -> #DIV/0! | O6: =IF(M6="","",M6*(1+O51)) -> 0 | P6: =IF(O6="","",O6/O$6) -> #DIV/0!
A7: 変動費 | E7: =SUM(E8:E14) -> 0 | F7: =IF(E7=0,"",E7/E$6) | G7: =SUM(G8:G14) -> 0 | H7: =IF(G7=0,"",G7/G$6) | I7: =SUM(I8:I14) -> 0 | J7: =IF(I7=0,"",I7/I$6) | K7: =SUM(K8:K14) -> 0 | L7: =IF(K7=0,"",K7/K$6) | M7: =SUM(M8:M14) -> 0 | N7: =IF(M7=0,"",M7/M$6) | O7: =SUM(O8:O14) -> 0 | P7: =IF(O7=0,"",O7/O$6) | S7: =E5 -> 2022年2月1日～2023年1月31日 | T7: =G4 -> 計画1期 | U7: =I4 -> 計画2期 | V7: =K4 -> 計画3期 | W7: =M4 -> 計画4期 | X7: =O4 -> 計画5期
B8: 売上原価 | C8: 製造原価 | D8: 材料費 | E8: ='財務諸表（入力）'!J96 -> 0 | F8: =IF(E8=0,"",E8/E$6) | G8: =IF(E8=0,0,G$6*H8) -> 0 | H8: =H54 | I8: =IF(G8=0,0,I$6*J8) -> 0 | J8: =J54 | K8: =IF(I8=0,0,K$6*L8) -> 0 | L8: =L54 | M8: =IF(K8=0,0,M$6*N8) -> 0 | N8: =N54 | O8: =IF(M8=0,0,O$6*P8) -> 0 | P8: =P54 | R8: 売上高 | S8: =E6 -> 0 | T8: =G6 -> 0 | U8: =I6 -> 0 | V8: =K6 -> 0 | W8: =M6 -> 0 | X8: =O6 -> 0
D9: 変動労務費 | E9: =SUMIF('財務諸表（入力）'!C97:D100,"V",'財務諸表（入力）'!D97:D100) -> 0 | F9: =IF(E9=0,"",E9/E$6) | G9: =IF(E9=0,0,G6*H65) -> 0 | H9: =H65 | I9: =IF(G9=0,0,I6*J65) -> 0 | J9: =J65 | K9: =IF(I9=0,0,K6*L65) -> 0 | L9: =L65 | M9: =IF(K9=0,0,M6*N65) -> 0 | N9: =N65 | O9: =IF(M9=0,0,O6*P65) -> 0 | P9: =P65 | R9: 損益分岐点売上高 | S9: =E33 -> #VALUE! | T9: =G33 -> #VALUE! | U9: =I33 -> #VALUE! | V9: =K33 -> #VALUE! | W9: =M33 -> #VALUE! | X9: =O33 -> #VALUE!
D10: 外注費 | E10: ='財務諸表（入力）'!J103 -> 0 | F10: =IF(E10=0,"",E10/E$6) | G10: =IF(E10=0,0,G$6*H10) -> 0 | H10: =H55 | I10: =IF(G10=0,0,I$6*J10) -> 0 | J10: =J55 | K10: =IF(I10=0,0,K$6*L10) -> 0 | L10: =L55 | M10: =IF(K10=0,0,M$6*N10) -> 0 | N10: =N55 | O10: =IF(M10=0,0,O$6*P10) -> 0 | P10: =P55 | R10: 変動費 | S10: =E7 -> 0 | T10: =G7 -> 0 | U10: =I7 -> 0 | V10: =K7 -> 0 | W10: =M7 -> 0 | X10: =O7 -> 0
D11: 経費他 | E11: =SUMIF('財務諸表（入力）'!C104:C116,"V",'財務諸表（入力）'!J104:J116)-'財務諸表（入力）'!J121 -> 0 | F11: =IF(E11=0,"",E11/E$6) | G11: =IF(E11=0,0,G$6*H11) -> 0 | H11: =H56 | I11: =IF(G11=0,0,I$6*J11) -> 0 | J11: =J56 | K11: =IF(I11=0,0,K$6*L11) -> 0 | L11: =L56 | M11: =IF(K11=0,0,M$6*N11) -> 0 | N11: =N56 | O11: =IF(M11=0,0,O$6*P11) -> 0 | P11: =P56 | R11: 固定費 | S11: =E16 -> 0 | T11: =G16 -> 0 | U11: =I16 -> 0 | V11: =K16 -> 0 | W11: =M16 -> 0 | X11: =O16 -> 0
C12: 商品仕入 | E12: ='財務諸表（入力）'!J131 -> 0 | F12: =IF(E12=0,"",E12/E$6) | G12: =IF(E12=0,0,G$6*H12) -> 0 | H12: =H57 | I12: =IF(G12=0,0,I$6*J12) -> 0 | J12: =J57 | K12: =IF(I12=0,0,K$6*L12) -> 0 | L12: =L57 | M12: =IF(K12=0,0,M$6*N12) -> 0 | N12: =N57 | O12: =IF(M12=0,0,O$6*P12) -> 0 | P12: =P57 | R12: 限界利益率 | S12: =F15 | T12: =H15 | U12: =J15 | V12: =L15 | W12: =N15 | X12: =P15
C13: 棚卸資産増減 | E13: ='財務諸表（入力）'!J130-'財務諸表（入力）'!J134-'財務諸表（入力）'!J133+'財務諸表（入力）'!J118-'財務諸表（入力）'!J120-'財務諸表（入力）'!J121 -> 0 | F13: =IF(E13=0,"",E13/E$6) | G13: =E61-G61 -> 0 | H13: =IF(G13="","",G13/G$6) -> #DIV/0! | I13: =G61-I61 -> 0 | J13: =IF(I13="","",I13/I$6) -> #DIV/0! | K13: =I61-K61 -> 0 | L13: =IF(K13="","",K13/K$6) -> #DIV/0! | M13: =K61-M61 -> 0 | N13: =IF(M13="","",M13/M$6) -> #DIV/0! | O13: =M61-O61 -> 0 | P13: =IF(O13="","",O13/O$6) -> #DIV/0! | R13: 損益分岐点比率 | S13: =F33 -> #VALUE! | T13: =H33 -> #VALUE! | U13: =J33 -> #VALUE! | V13: =L33 -> #VALUE! | W13: =N33 -> #VALUE! | X13: =P33 -> #VALUE!
B14: 販売管理費 | E14: =SUMIF('財務諸表（入力）'!C144:C155,"V",'財務諸表（入力）'!J144:J155) -> 0 | F14: =IF(E14=0,"",E14/E$6) | G14: =IF(E14=0,0,G$6*H14) -> 0 | H14: =H58 | I14: =IF(G14=0,0,I$6*J14) -> 0 | J14: =J58 | K14: =IF(I14=0,0,K$6*L14) -> 0 | L14: =L58 | M14: =IF(K14=0,0,M$6*N14) -> 0 | N14: =N58 | O14: =IF(M14=0,0,O$6*P14) -> 0 | P14: =P58
A15: 限界利益 | E15: =E6-E7 -> 0 | F15: =IF(E15=0,"",E15/E$6) | G15: =G6-G7 -> 0 | H15: =IF(G15=0,"",G15/G$6) | I15: =I6-I7 -> 0 | J15: =IF(I15=0,"",I15/I$6) | K15: =K6-K7 -> 0 | L15: =IF(K15=0,"",K15/K$6) | M15: =M6-M7 -> 0 | N15: =IF(M15=0,"",M15/M$6) | O15: =O6-O7 -> 0 | P15: =IF(O15=0,"",O15/O$6)
A16: 固定費 | E16: =SUM(E17:E23) -> 0 | F16: =IF(E16=0,"",E16/E$6) | G16: =SUM(G17:G23) -> 0 | H16: =IF(G16=0,"",G16/G$6) | I16: =SUM(I17:I23) -> 0 | J16: =IF(I16=0,"",I16/I$6) | K16: =SUM(K17:K23) -> 0 | L16: =IF(K16=0,"",K16/K$6) | M16: =SUM(M17:M23) -> 0 | N16: =IF(M16=0,"",M16/M$6) | O16: =SUM(O17:O23) -> 0 | P16: =IF(O16=0,"",O16/O$6)
B17: 固定労務費 | E17: =SUMIF('財務諸表（入力）'!C97:C100,"F",'財務諸表（入力）'!J97:J100) -> 0 | F17: =IF(E17=0,"",E17/E$6) | G17: =E17+G67 -> 0 | H17: =IF(G17=0,"",G17/G$6) | I17: =G17+I67 -> 0 | J17: =IF(I17=0,"",I17/I$6) | K17: =I17+K67 -> 0 | L17: =IF(K17=0,"",K17/K$6) | M17: =K17+M67 -> 0 | N17: =IF(M17=0,"",M17/M$6) | O17: =M17+O67 -> 0 | P17: =IF(O17=0,"",O17/O$6)
B18: 減価償却費 | E18: ='財務諸表（入力）'!J102+'財務諸表（入力）'!J142 -> 0 | F18: =IF(E18=0,"",E18/E$6) | H18: =IF(G18=0,"",G18/G$6) | J18: =IF(I18=0,"",I18/I$6) | L18: =IF(K18=0,"",K18/K$6) | N18: =IF(M18=0,"",M18/M$6) | P18: =IF(O18=0,"",O18/O$6)
B19: 経費他 | E19: =SUMIF('財務諸表（入力）'!C104:C116,"F",'財務諸表（入力）'!J104:J116) -> 0 | F19: =IF(E19=0,"",E19/E$6) | G19: =E19+G71 -> 0 | H19: =IF(G19=0,"",G19/G$6) | I19: =G19+I71 -> 0 | J19: =IF(I19=0,"",I19/I$6) | K19: =I19+K71 -> 0 | L19: =IF(K19=0,"",K19/K$6) | M19: =K19+M71 -> 0 | N19: =IF(M19=0,"",M19/M$6) | O19: =M19+O71 -> 0 | P19: =IF(O19=0,"",O19/O$6)
B20: 販管人件費 | E20: =SUM('財務諸表（入力）'!J138:J141) -> 0 | F20: =IF(E20=0,"",E20/E$6) | G20: =E20+G68 -> 0 | H20: =IF(G20=0,"",G20/G$6) | I20: =G20+I68 -> 0 | J20: =IF(I20=0,"",I20/I$6) | K20: =I20+K68 -> 0 | L20: =IF(K20=0,"",K20/K$6) | M20: =K20+M68 -> 0 | N20: =IF(M20=0,"",M20/M$6) | O20: =M20+O68 -> 0 | P20: =IF(O20=0,"",O20/O$6)
B21: その他販管費 | E21: =SUMIF('財務諸表（入力）'!C144:C155,"F",'財務諸表（入力）'!J144:J155) -> 0 | F21: =IF(E21=0,"",E21/E$6) | G21: =E21+G72 -> 0 | H21: =IF(G21=0,"",G21/G$6) | I21: =G21+I72 -> 0 | J21: =IF(I21=0,"",I21/I$6) | K21: =I21+K72 -> 0 | L21: =IF(K21=0,"",K21/K$6) | M21: =K21+M72 -> 0 | N21: =IF(M21=0,"",M21/M$6) | O21: =M21+O72 -> 0 | P21: =IF(O21=0,"",O21/O$6)
B22: 営業外 | C22: 支払利息 | E22: ='財務諸表（入力）'!J163 -> 0 | F22: =IF(E22=0,"",E22/E$6) | H22: =IF(G22=0,"",G22/G$6) | J22: =IF(I22=0,"",I22/I$6) | L22: =IF(K22=0,"",K22/K$6) | N22: =IF(M22=0,"",M22/M$6) | P22: =IF(O22=0,"",O22/O$6)
C23: その他収支 | E23: ='財務諸表（入力）'!J164-'財務諸表（入力）'!J162 -> 0 | F23: =IF(E23=0,"",E23/E$6) | G23: =E23+G73 -> 0 | H23: =IF(G23=0,"",G23/G$6) | I23: =G23+I73 -> 0 | J23: =IF(I23=0,"",I23/I$6) | K23: =I23+K73 -> 0 | L23: =IF(K23=0,"",K23/K$6) | M23: =K23+M73 -> 0 | N23: =IF(M23=0,"",M23/M$6) | O23: =M23+O73 -> 0 | P23: =IF(O23=0,"",O23/O$6)
A24: 経常利益 | E24: =E15-E16 -> 0 | F24: =IF(E24=0,"",E24/E$6) | G24: =G15-G16 -> 0 | H24: =IF(G24=0,"",G24/G$6) | I24: =I15-I16 -> 0 | J24: =IF(I24=0,"",I24/I$6) | K24: =K15-K16 -> 0 | L24: =IF(K24=0,"",K24/K$6) | M24: =M15-M16 -> 0 | N24: =IF(M24=0,"",M24/M$6) | O24: =O15-O16 -> 0 | P24: =IF(O24=0,"",O24/O$6)
B25: 特別利益 | E25: ='財務諸表（入力）'!J167 -> 0 | F25: =IF(E25=0,"",E25/E$6) | H25: =IF(G25=0,"",G25/G$6) | J25: =IF(I25=0,"",I25/I$6) | L25: =IF(K25=0,"",K25/K$6) | N25: =IF(M25=0,"",M25/M$6) | P25: =IF(O25=0,"",O25/O$6)
B26: 特別損失 | E26: ='財務諸表（入力）'!J168 -> 0 | F26: =IF(E26=0,"",E26/E$6) | H26: =IF(G26=0,"",G26/G$6) | J26: =IF(I26=0,"",I26/I$6) | L26: =IF(K26=0,"",K26/K$6) | N26: =IF(M26=0,"",M26/M$6) | P26: =IF(O26=0,"",O26/O$6)
A27: 税引前利益 | E27: =E24+E25-E26 -> 0 | F27: =IF(E27=0,"",E27/E$6) | G27: =G24+G25-G26 -> 0 | H27: =IF(G27=0,"",G27/G$6) | I27: =I24+I25-I26 -> 0 | J27: =IF(I27=0,"",I27/I$6) | K27: =K24+K25-K26 -> 0 | L27: =IF(K27=0,"",K27/K$6) | M27: =M24+M25-M26 -> 0 | N27: =IF(M27=0,"",M27/M$6) | O27: =O24+O25-O26 -> 0 | P27: =IF(O27=0,"",O27/O$6)
B28: 法人税等 | E28: ='財務諸表（入力）'!J170 -> 0 | F28: =IF(E28=0,"",E28/E$6) | G28: =IF(G27<0,"0",G27*0.4-G29) -> 0 | H28: =IF(G28=0,"",G28/G$6) | I28: =IF(I27<0,"0",I27*0.4-I29) -> 0 | J28: =IF(I28=0,"",I28/I$6) | K28: =IF(K27<0,"0",K27*0.4-K29) -> 0 | L28: =IF(K28=0,"",K28/K$6) | M28: =IF(M27<0,"0",M27*0.4-M29) -> 0 | N28: =IF(M28=0,"",M28/M$6) | O28: =IF(O27<0,"0",O27*0.4-O29) -> 0 | P28: =IF(O28=0,"",O28/O$6)
B29: 法人税等調整額 | F29: =IF(E29=0,"",E29/E$6) | H29: =IF(G29=0,"",G29/G$6) | J29: =IF(I29=0,"",I29/I$6) | L29: =IF(K29=0,"",K29/K$6) | N29: =IF(M29=0,"",M29/M$6) | P29: =IF(O29=0,"",O29/O$6)
A30: 税引後利益 | E30: =E27-E28-E29 -> 0 | F30: =IF(E30=0,"",E30/E$6) | G30: =G27-G28-G29 -> 0 | H30: =IF(G30=0,"",G30/G$6) | I30: =I27-I28-I29 -> 0 | J30: =IF(I30=0,"",I30/I$6) | K30: =K27-K28-K29 -> 0 | L30: =IF(K30=0,"",K30/K$6) | M30: =M27-M28-M29 -> 0 | N30: =IF(M30=0,"",M30/M$6) | O30: =O27-O28-O29 -> 0 | P30: =IF(O30=0,"",O30/O$6)
A31: キャッシュフロー | E31: =E18+E30 -> 0 | F31: =IF(E31=0,"",E31/E$6) | G31: =G18+G30 -> 0 | H31: =IF(G31=0,"",G31/G$6) | I31: =I18+I30 -> 0 | J31: =IF(I31=0,"",I31/I$6) | K31: =K18+K30 -> 0 | L31: =IF(K31=0,"",K31/K$6) | M31: =M18+M30 -> 0 | N31: =IF(M31=0,"",M31/M$6) | O31: =O18+O30 -> 0 | P31: =IF(O31=0,"",O31/O$6)
A33: 損益分岐点売上高／比率 （経常利益ベース） | E33: =E16/F15 -> #VALUE! | F33: =E33/E6 -> #VALUE! | G33: =G16/H15 -> #VALUE! | H33: =G33/G6 -> #VALUE! | I33: =I16/J15 -> #VALUE! | J33: =I33/I6 -> #VALUE! | K33: =K16/L15 -> #VALUE! | L33: =K33/K6 -> #VALUE! | M33: =M16/N15 -> #VALUE! | N33: =M33/M6 -> #VALUE! | O33: =O16/P15 -> #VALUE! | P33: =O33/O6 -> #VALUE!
A35: 【限界利益率・損益分岐点比率の推移】
A48: ■ 入力項目
A50: 【売上予測】 | G50: (増減率）
A51: 売上高 | E51: =E6 -> 0 | F51: - | H51: - | J51: - | L51: - | N51: - | P51: -
A53: 【変動費率調整】 | G53: （増減率）
A54: 材料費 | E54: =E8 -> 0 | F54: =F8 | H54: =IF(G54="",F54,F54+G54) | J54: =IF(I54="",H54,H54+I54) | L54: =IF(K54="",J54,J54+K54) | N54: =IF(M54="",L54,L54+M54) | P54: =IF(O54="",N54,N54+O54)
A55: 外注費 | E55: =E10 -> 0 | F55: =F10 | H55: =IF(G55="",F55,F55+G55) | J55: =IF(I55="",H55,H55+I55) | L55: =IF(K55="",J55,J55+K55) | N55: =IF(M55="",L55,L55+M55) | P55: =IF(O55="",N55,N55+O55)
A56: 経費他 | E56: =E11 -> 0 | F56: =F11 | H56: =IF(G56="",F56,F56+G56) | J56: =IF(I56="",H56,H56+I56) | L56: =IF(K56="",J56,J56+K56) | N56: =IF(M56="",L56,L56+M56) | P56: =IF(O56="",N56,N56+O56)
...

Sheet 【総合所見】
A3: 【財務分析結果のまとめ】
A5: １．収益面 （総資本利益率、売上利益率、資産回転期間（効率性）、損益分岐点分析等）
A15: ２．資金面 （運転資金分析、資金運用表＆移動表、長期借入返済能力等）
A25: ３．財務バランス、安全性等 （流動・固定のバランス、自己資本比率、債務償還年数等）
A35: ４．その他 （成長性、生産性、その他全般）
A45: ５．所見 （業界比での特徴、３期の推移傾向、長所・リスクの把握、課題（仮説）の検証等）

Sheet 部門別売上sim
A1: ='財務諸表（入力）'!D1 -> 0
A3: １．直近期の部門別売上・利益推定
E5: 直近期実績 | G5: 部門別売上構成 [上段：部門・商品等区分、中段：売上構成比、下段：人員概算] ← ヒアリングに基づき設定
E6: ='財務諸表（入力）'!J4 -> 2022年2月1日～2023年1月31日 | F6: 売上比 | H6: 売上比 | J6: 売上比 | L6: 売上比 | N6: 売上比 | P6: 売上比 | R6: 合計 | S6: 売上比
R7: =G7+I7+K7+M7+O7 -> 0
R8: =G8+I8+K8+M8+O8 -> 0
A9: 売上高 | E9: ='財務諸表（入力）'!J129 -> 0 | F9: =IF(E9=0,"",E9/E$9) | G9: =$E$9*G7 -> 0 | H9: =IF(G9=0,"",G9/G$9) | I9: =$E$9*I7 -> 0 | J9: =IF(I9=0,"",I9/I$9) | K9: =$E$9*K7 -> 0 | L9: =IF(K9=0,"",K9/K$9) | M9: =$E$9*M7 -> 0 | N9: =IF(M9=0,"",M9/M$9) | O9: =$E$9*O7 -> 0 | P9: =IF(O9=0,"",O9/O$9) | R9: =G9+I9+K9+M9+O9 -> 0 | S9: =IF(R9=0,"",R9/R$9)
A10: 売上原価 | B10: 変動費 | E10: ='財務諸表（入力）'!J96+SUMIF('財務諸表（入力）'!$C$97:$C$116,"V",'財務諸表（入力）'!$J$97:$J$116)+'財務諸表（入力）'!J122+'財務諸表（入力）'!J131+'財務諸表（入力）'!J135-'財務諸表（入力）'!$J121 -> 0 | F10: =IF(E10=0,"",E10/E$9) | G10: =G13-G11-G12 -> #DIV/0! | H10: =IF(G10=0,"",G10/G$9) -> #DIV/0! | I10: =I13-I11-I12 -> #DIV/0! | J10: =IF(I10=0,"",I10/I$9) -> #DIV/0! | K10: =K13-K11-K12 -> #DIV/0! | L10: =IF(K10=0,"",K10/K$9) -> #DIV/0! | M10: =M13-M11-M12 -> #DIV/0! | N10: =IF(M10=0,"",M10/M$9) -> #DIV/0! | O10: =O13-O11-O12 -> #DIV/0! | P10: =IF(O10=0,"",O10/O$9) -> #DIV/0! | R10: =G10+I10+K10+M10+O10 -> #DIV/0! | S10: =IF(R10=0,"",R10/R$9) -> #DIV/0!
B11: 固定費 | C11: 労務費 | E11: =SUMIF('財務諸表（入力）'!$C$97:$C$100,"F",'財務諸表（入力）'!$J$97:$J$100) -> 0 | F11: =IF(E11=0,"",E11/E$9) | G11: =$E11*G8/$R8 -> #DIV/0! | H11: =IF(G11=0,"",G11/G$9) -> #DIV/0! | I11: =$E11*I8/$R8 -> #DIV/0! | J11: =IF(I11=0,"",I11/I$9) -> #DIV/0! | K11: =$E11*K8/$R8 -> #DIV/0! | L11: =IF(K11=0,"",K11/K$9) -> #DIV/0! | M11: =$E11*M8/$R8 -> #DIV/0! | N11: =IF(M11=0,"",M11/M$9) -> #DIV/0! | O11: =$E11*O8/$R8 -> #DIV/0! | P11: =IF(O11=0,"",O11/O$9) -> #DIV/0! | R11: =G11+I11+K11+M11+O11 -> #DIV/0! | S11: =IF(R11=0,"",R11/R$9) -> #DIV/0!
C12: 経費 | E12: =SUMIF('財務諸表（入力）'!$C$102:$C$116,"F",'財務諸表（入力）'!$J$102:$J$116) -> 0 | F12: =IF(E12=0,"",E12/E$9) | G12: =$E12*G7 -> 0 | H12: =IF(G12=0,"",G12/G$9) | I12: =$E12*I7 -> 0 | J12: =IF(I12=0,"",I12/I$9) | K12: =$E12*K7 -> 0 | L12: =IF(K12=0,"",K12/K$9) | M12: =$E12*M7 -> 0 | N12: =IF(M12=0,"",M12/M$9) | O12: =$E12*O7 -> 0 | P12: =IF(O12=0,"",O12/O$9) | R12: =G12+I12+K12+M12+O12 -> 0 | S12: =IF(R12=0,"",R12/R$9)
A13: 合計 | E13: =E10+E11+E12 -> 0 | F13: =IF(E13=0,"",E13/E$9) | G13: =G9-G14 -> 0 | H13: =IF(G13=0,"",G13/G$9) | I13: =I9-I14 -> 0 | J13: =IF(I13=0,"",I13/I$9) | K13: =K9-K14 -> 0 | L13: =IF(K13=0,"",K13/K$9) | M13: =M9-M14 -> 0 | N13: =IF(M13=0,"",M13/M$9) | O13: =O9-O14 -> 0 | P13: =IF(O13=0,"",O13/O$9) | R13: =G13+I13+K13+M13+O13 -> 0 | S13: =IF(R13=0,"",R13/R$9) | T13: （差異）
A14: 売上総利益 | E14: =E9-E13 -> 0 | F14: =IF(E14=0,"",E14/E$9) | G14: =G9*H14 -> 0 | I14: =I9*J14 -> 0 | K14: =K9*L14 -> 0 | M14: =M9*N14 -> 0 | O14: =O9*P14 -> 0 | R14: =G14+I14+K14+M14+O14 -> 0 | S14: =IF(R14=0,"",R14/R$9) | T14: =R14-E14 -> 0 | U14: =S14-F14 -> #VALUE!
A15: 販管費 | B15: 変動費 | E15: =SUMIF('財務諸表（入力）'!$C$143:$C$155,"V",'財務諸表（入力）'!$J$143:$J$155) -> 0 | F15: =IF(E15=0,"",E15/E$9) | G15: =$E15*G$7 -> 0 | H15: =IF(G15=0,"",G15/G$9) | I15: =$E15*I$7 -> 0 | J15: =IF(I15=0,"",I15/I$9) | K15: =$E15*K$7 -> 0 | L15: =IF(K15=0,"",K15/K$9) | M15: =$E15*M$7 -> 0 | N15: =IF(M15=0,"",M15/M$9) | O15: =$E15*O$7 -> 0 | P15: =IF(O15=0,"",O15/O$9) | R15: =G15+I15+K15+M15+O15 -> 0 | S15: =IF(R15=0,"",R15/R$9)
B16: 固定費 | C16: 人件費 | E16: =SUM('財務諸表（入力）'!J138:J141) -> 0 | F16: =IF(E16=0,"",E16/E$9) | G16: =$E16*G8/$R8 -> #DIV/0! | H16: =IF(G16=0,"",G16/G$9) -> #DIV/0! | I16: =$E16*I8/$R8 -> #DIV/0! | J16: =IF(I16=0,"",I16/I$9) -> #DIV/0! | K16: =$E16*K8/$R8 -> #DIV/0! | L16: =IF(K16=0,"",K16/K$9) -> #DIV/0! | M16: =$E16*M8/$R8 -> #DIV/0! | N16: =IF(M16=0,"",M16/M$9) -> #DIV/0! | O16: =$E16*O8/$R8 -> #DIV/0! | P16: =IF(O16=0,"",O16/O$9) -> #DIV/0! | R16: =G16+I16+K16+M16+O16 -> #DIV/0! | S16: =IF(R16=0,"",R16/R$9) -> #DIV/0!
C17: 減価償却費 | E17: ='財務諸表（入力）'!J142 -> 0 | F17: =IF(E17=0,"",E17/E$9) | G17: =$E17*G$7 -> 0 | H17: =IF(G17=0,"",G17/G$9) | I17: =$E17*I$7 -> 0 | J17: =IF(I17=0,"",I17/I$9) | K17: =$E17*K$7 -> 0 | L17: =IF(K17=0,"",K17/K$9) | M17: =$E17*M$7 -> 0 | N17: =IF(M17=0,"",M17/M$9) | O17: =$E17*O$7 -> 0 | P17: =IF(O17=0,"",O17/O$9) | R17: =G17+I17+K17+M17+O17 -> 0 | S17: =IF(R17=0,"",R17/R$9)
C18: その他 | E18: =SUMIF('財務諸表（入力）'!$C$143:$C$155,"F",'財務諸表（入力）'!$J$143:$J$155) -> 0 | F18: =IF(E18=0,"",E18/E$9) | G18: =$E18*G$7 -> 0 | H18: =IF(G18=0,"",G18/G$9) | I18: =$E18*I$7 -> 0 | J18: =IF(I18=0,"",I18/I$9) | K18: =$E18*K$7 -> 0 | L18: =IF(K18=0,"",K18/K$9) | M18: =$E18*M$7 -> 0 | N18: =IF(M18=0,"",M18/M$9) | O18: =$E18*O$7 -> 0 | P18: =IF(O18=0,"",O18/O$9) | R18: =G18+I18+K18+M18+O18 -> 0 | S18: =IF(R18=0,"",R18/R$9)
D19: 合計 | E19: =E15+E16+E17+E18 -> 0 | F19: =IF(E19=0,"",E19/E$9) | G19: =G15+G16+G17+G18 -> #DIV/0! | H19: =IF(G19=0,"",G19/G$9) -> #DIV/0! | I19: =I15+I16+I17+I18 -> #DIV/0! | J19: =IF(I19=0,"",I19/I$9) -> #DIV/0! | K19: =K15+K16+K17+K18 -> #DIV/0! | L19: =IF(K19=0,"",K19/K$9) -> #DIV/0! | M19: =M15+M16+M17+M18 -> #DIV/0! | N19: =IF(M19=0,"",M19/M$9) -> #DIV/0! | O19: =O15+O16+O17+O18 -> #DIV/0! | P19: =IF(O19=0,"",O19/O$9) -> #DIV/0! | R19: =G19+I19+K19+M19+O19 -> #DIV/0! | S19: =IF(R19=0,"",R19/R$9) -> #DIV/0!
A20: 営業利益 | E20: =E14-E19 -> 0 | F20: =IF(E20=0,"",E20/E$9) | G20: =G14-G19 -> #DIV/0! | H20: =IF(G20=0,"",G20/G$9) -> #DIV/0! | I20: =I14-I19 -> #DIV/0! | J20: =IF(I20=0,"",I20/I$9) -> #DIV/0! | K20: =K14-K19 -> #DIV/0! | L20: =IF(K20=0,"",K20/K$9) -> #DIV/0! | M20: =M14-M19 -> #DIV/0! | N20: =IF(M20=0,"",M20/M$9) -> #DIV/0! | O20: =O14-O19 -> #DIV/0! | P20: =IF(O20=0,"",O20/O$9) -> #DIV/0! | R20: =G20+I20+K20+M20+O20 -> #DIV/0! | S20: =IF(R20=0,"",R20/R$9) -> #DIV/0!
A21: 営業外 | B21: 営業外収入 | E21: ='財務諸表（入力）'!J162 -> 0 | F21: =IF(E21=0,"",E21/E$9) | G21: =$E21*G$7 -> 0 | H21: =IF(G21=0,"",G21/G$9) | I21: =$E21*I$7 -> 0 | J21: =IF(I21=0,"",I21/I$9) | K21: =$E21*K$7 -> 0 | L21: =IF(K21=0,"",K21/K$9) | M21: =$E21*M$7 -> 0 | N21: =IF(M21=0,"",M21/M$9) | O21: =$E21*O$7 -> 0 | P21: =IF(O21=0,"",O21/O$9) | R21: =G21+I21+K21+M21+O21 -> 0 | S21: =IF(R21=0,"",R21/R$9)
B22: 営業外費用 | E22: ='財務諸表（入力）'!J165 -> 0 | F22: =IF(E22=0,"",E22/E$9) | G22: =$E22*G$7 -> 0 | H22: =IF(G22=0,"",G22/G$9) | I22: =$E22*I$7 -> 0 | J22: =IF(I22=0,"",I22/I$9) | K22: =$E22*K$7 -> 0 | L22: =IF(K22=0,"",K22/K$9) | M22: =$E22*M$7 -> 0 | N22: =IF(M22=0,"",M22/M$9) | O22: =$E22*O$7 -> 0 | P22: =IF(O22=0,"",O22/O$9) | R22: =G22+I22+K22+M22+O22 -> 0 | S22: =IF(R22=0,"",R22/R$9)
A23: 経常利益 | E23: =E20+E21-E22 -> 0 | F23: =IF(E23=0,"",E23/E$9) | G23: =G20+G21-G22 -> #DIV/0! | H23: =IF(G23=0,"",G23/G$9) -> #DIV/0! | I23: =I20+I21-I22 -> #DIV/0! | J23: =IF(I23=0,"",I23/I$9) -> #DIV/0! | K23: =K20+K21-K22 -> #DIV/0! | L23: =IF(K23=0,"",K23/K$9) -> #DIV/0! | M23: =M20+M21-M22 -> #DIV/0! | N23: =IF(M23=0,"",M23/M$9) -> #DIV/0! | O23: =O20+O21-O22 -> #DIV/0! | P23: =IF(O23=0,"",O23/O$9) -> #DIV/0! | R23: =G23+I23+K23+M23+O23 -> #DIV/0! | S23: =IF(R23=0,"",R23/R$9) -> #DIV/0!
A25: BEP | B25: 損益分岐点売上高・率 | E25: =(E11+E12+E16+E17+E18+E22-E21)/F26 -> #VALUE! | F25: =IF(E25=0,"",E25/E$9) -> #VALUE! | G25: =(G11+G12+G16+G17+G18+G22-G21)/H26 -> #DIV/0! | H25: =IF(G25=0,"",G25/G$9) -> #DIV/0! | I25: =(I11+I12+I16+I17+I18+I22-I21)/J26 -> #DIV/0! | J25: =IF(I25=0,"",I25/I$9) -> #DIV/0! | K25: =(K11+K12+K16+K17+K18+K22-K21)/L26 -> #DIV/0! | L25: =IF(K25=0,"",K25/K$9) -> #DIV/0! | M25: =(M11+M12+M16+M17+M18+M22-M21)/N26 -> #DIV/0! | N25: =IF(M25=0,"",M25/M$9) -> #DIV/0! | O25: =(O11+O12+O16+O17+O18+O22-O21)/P26 -> #DIV/0! | P25: =IF(O25=0,"",O25/O$9) -> #DIV/0!
B26: 限界利益額・率 | E26: =E9-E10-E15 -> 0 | F26: =IF(E26=0,"",E26/E$9) | G26: =G9-G10-G15 -> #DIV/0! | H26: =IF(G26=0,"",G26/G$9) -> #DIV/0! | I26: =I9-I10-I15 -> #DIV/0! | J26: =IF(I26=0,"",I26/I$9) -> #DIV/0! | K26: =K9-K10-K15 -> #DIV/0! | L26: =IF(K26=0,"",K26/K$9) -> #DIV/0! | M26: =M9-M10-M15 -> #DIV/0! | N26: =IF(M26=0,"",M26/M$9) -> #DIV/0! | O26: =O9-O10-O15 -> #DIV/0! | P26: =IF(O26=0,"",O26/O$9) -> #DIV/0!
B27: １人あたり人件費 （直接・間接全て） | E27: =(E11+E16)/R8 -> #DIV/0!
A29: ２．部門別売上・コストのシミュレーション
A30: [パターン①]
E31: 合計 上段：売上構成 下段：人員数 | F31: 売上比 | G31: =G6 -> 0 | H31: 売上比 | I31: =I6 -> 0 | J31: 売上比 | K31: =K6 -> 0 | L31: 売上比 | M31: =M6 -> 0 | N31: 売上比 | O31: =O6 -> 0 | P31: 売上比 | R31: 【コメント】
E32: =G32+I32+K32+M32+O32 -> 0
E33: =G33+I33+K33+M33+O33 -> 0
A34: 売上高 | F34: =IF(E34=0,"",E34/E$34) | G34: =$E$34*G32 -> 0 | H34: =IF(G34=0,"",G34/G$34) | I34: =$E$34*I32 -> 0 | J34: =IF(I34=0,"",I34/I$34) | K34: =$E$34*K32 -> 0 | L34: =IF(K34=0,"",K34/K$34) | M34: =$E$34*M32 -> 0 | N34: =IF(M34=0,"",M34/M$34) | O34: =$E$34*O32 -> 0 | P34: =IF(O34=0,"",O34/O$34) | V34: =G34+I34+K34+M34+O34 -> 0
A35: 売上原価 | B35: 変動費 | E35: =G35+I35+K35+M35+O35 -> #DIV/0! | F35: =IF(E35=0,"",E35/E$34) -> #DIV/0! | G35: =G34*H35 -> #DIV/0! | H35: =H10 -> #DIV/0! | I35: =I34*J35 -> #DIV/0! | J35: =J10 -> #DIV/0! | K35: =K34*L35 -> #DIV/0! | L35: =L10 -> #DIV/0! | M35: =M34*N35 -> #DIV/0! | N35: =N10 -> #DIV/0! | O35: =O34*P35 -> #DIV/0! | P35: =P10 -> #DIV/0! | V35: =G35+I35+K35+M35+O35 -> #DIV/0!
B36: 固定費 | C36: 労務費 | E36: =E11 -> 0 | F36: =IF(E36=0,"",E36/E$34) | G36: =$E36*G33/$E33 -> #DIV/0! | H36: =IF(G36=0,"",G36/G$34) -> #DIV/0! | I36: =$E36*I33/$E33 -> #DIV/0! | J36: =IF(I36=0,"",I36/I$34) -> #DIV/0! | K36: =$E36*K33/$E33 -> #DIV/0! | L36: =IF(K36=0,"",K36/K$34) -> #DIV/0! | M36: =$E36*M33/$E33 -> #DIV/0! | N36: =IF(M36=0,"",M36/M$34) -> #DIV/0! | O36: =$E36*O33/$E33 -> #DIV/0! | P36: =IF(O36=0,"",O36/O$34) -> #DIV/0! | V36: =G36+I36+K36+M36+O36 -> #DIV/0!
C37: 経費 | E37: =E12 -> 0 | F37: =IF(E37=0,"",E37/E$34) | G37: =$E37*G32 -> 0 | H37: =IF(G37=0,"",G37/G$34) | I37: =$E37*I32 -> 0 | J37: =IF(I37=0,"",I37/I$34) | K37: =$E37*K32 -> 0 | L37: =IF(K37=0,"",K37/K$34) | M37: =$E37*M32 -> 0 | N37: =IF(M37=0,"",M37/M$34) | O37: =$E37*O32 -> 0 | P37: =IF(O37=0,"",O37/O$34) | V37: =G37+I37+K37+M37+O37 -> 0
A38: 合計 | E38: =SUM(E35:E37) -> #DIV/0! | F38: =IF(E38=0,"",E38/E$34) -> #DIV/0! | G38: =SUM(G35:G37) -> #DIV/0! | H38: =IF(G38=0,"",G38/G$34) -> #DIV/0! | I38: =SUM(I35:I37) -> #DIV/0! | J38: =IF(I38=0,"",I38/I$34) -> #DIV/0! | K38: =SUM(K35:K37) -> #DIV/0! | L38: =IF(K38=0,"",K38/K$34) -> #DIV/0! | M38: =SUM(M35:M37) -> #DIV/0! | N38: =IF(M38=0,"",M38/M$34) -> #DIV/0! | O38: =SUM(O35:O37) -> #DIV/0! | P38: =IF(O38=0,"",O38/O$34) -> #DIV/0! | V38: =G38+I38+K38+M38+O38 -> #DIV/0!
A39: 売上総利益 | E39: =E34-E38 -> #DIV/0! | F39: =IF(E39=0,"",E39/E$34) -> #DIV/0! | G39: =G34-G38 -> #DIV/0! | H39: =IF(G39=0,"",G39/G$34) -> #DIV/0! | I39: =I34-I38 -> #DIV/0! | J39: =IF(I39=0,"",I39/I$34) -> #DIV/0! | K39: =K34-K38 -> #DIV/0! | L39: =IF(K39=0,"",K39/K$34) -> #DIV/0! | M39: =M34-M38 -> #DIV/0! | N39: =IF(M39=0,"",M39/M$34) -> #DIV/0! | O39: =O34-O38 -> #DIV/0! | P39: =IF(O39=0,"",O39/O$34) -> #DIV/0! | V39: =G39+I39+K39+M39+O39 -> #DIV/0!
A40: 販管費 | B40: 変動費 | E40: =G40+I40+K40+M40+O40 -> 0 | F40: =IF(E40=0,"",E40/E$34) | G40: =IF(H40="",0,G34*H40) -> 0 | H40: =H15 | I40: =IF(J40="",0,I34*J40) -> 0 | J40: =J15 | K40: =IF(L40="",0,K34*L40) -> 0 | L40: =L15 | M40: =IF(N40="",0,M34*N40) -> 0 | N40: =N15 | O40: =IF(P40="",0,O34*P40) -> 0 | P40: =P15
B41: 固定費 | C41: 人件費 | E41: =G41+I41+K41+M41+O41 -> #DIV/0! | F41: =IF(E41=0,"",E41/E$34) -> #DIV/0! | G41: =$E16*G33/$E33 -> #DIV/0! | H41: =IF(G41=0,"",G41/G$34) -> #DIV/0! | I41: =$E16*I33/$E33 -> #DIV/0! | J41: =IF(I41=0,"",I41/I$34) -> #DIV/0! | K41: =$E16*K33/$E33 -> #DIV/0! | L41: =IF(K41=0,"",K41/K$34) -> #DIV/0! | M41: =$E16*M33/$E33 -> #DIV/0! | N41: =IF(M41=0,"",M41/M$34) -> #DIV/0! | O41: =$E16*O33/$E33 -> #DIV/0! | P41: =IF(O41=0,"",O41/O$34) -> #DIV/0! | V41: =G41+I41+K41+M41+O41 -> #DIV/0!
C42: 減価償却費 | E42: =G42+I42+K42+M42+O42 -> 0 | F42: =IF(E42=0,"",E42/E$34) | G42: =$E17*G$32 -> 0 | H42: =IF(G42=0,"",G42/G$34) | I42: =$E17*I$32 -> 0 | J42: =IF(I42=0,"",I42/I$34) | K42: =$E17*K$32 -> 0 | L42: =IF(K42=0,"",K42/K$34) | M42: =$E17*M$32 -> 0 | N42: =IF(M42=0,"",M42/M$34) | O42: =$E17*O$32 -> 0 | P42: =IF(O42=0,"",O42/O$34) | V42: =G42+I42+K42+M42+O42 -> 0
C43: その他 | E43: =G43+I43+K43+M43+O43 -> 0 | F43: =IF(E43=0,"",E43/E$34) | G43: =$E18*G$32 -> 0 | H43: =IF(G43=0,"",G43/G$34) | I43: =$E18*I$32 -> 0 | J43: =IF(I43=0,"",I43/I$34) | K43: =$E18*K$32 -> 0 | L43: =IF(K43=0,"",K43/K$34) | M43: =$E18*M$32 -> 0 | N43: =IF(M43=0,"",M43/M$34) | O43: =$E18*O$32 -> 0 | P43: =IF(O43=0,"",O43/O$34) | V43: =G43+I43+K43+M43+O43 -> 0
D44: 合計 | E44: =SUM(E40:E43) -> #DIV/0! | F44: =IF(E44=0,"",E44/E$34) -> #DIV/0! | G44: =SUM(G40:G43) -> #DIV/0! | H44: =IF(G44=0,"",G44/G$34) -> #DIV/0! | I44: =SUM(I40:I43) -> #DIV/0! | J44: =IF(I44=0,"",I44/I$34) -> #DIV/0! | K44: =SUM(K40:K43) -> #DIV/0! | L44: =IF(K44=0,"",K44/K$34) -> #DIV/0! | M44: =SUM(M40:M43) -> #DIV/0! | N44: =IF(M44=0,"",M44/M$34) -> #DIV/0! | O44: =SUM(O40:O43) -> #DIV/0! | P44: =IF(O44=0,"",O44/O$34) -> #DIV/0! | V44: =G44+I44+K44+M44+O44 -> #DIV/0!
...

Sheet CF計算書
B1: キャッシュ・フロー計算書（概算・参考）
B4: キャッシュ・フロー計算書
B5: ='財務諸表（入力）'!J4 -> 2022年2月1日～2023年1月31日
C6: =CFワークシート!J7 -> （単位：千円） | E6: （単位：百万円）
B7: 項 目 | C7: 金 額 | E7: （単位：千円）
B8: Ⅰ 営業活動によるキャッシュ・フロー | E8: （単位：円）
B9: （１）当期純利益（＋） | C9: =CFワークシート!D44 -> 0
B10: （２）非資金の費用項目
B11: １．減価償却費（＋） | C11: =CFワークシート!D48 -> 0
B12: ２．諸引当金の増加（＋）・減少（－）額 | C12: =CFワークシート!J13+CFワークシート!J18-CFワークシート!E16-CFワークシート!E25 -> 0
B13: （３）回収・支払サイト
B14: １．受取手形の増加（－）・減少（＋）額 | C14: =CFワークシート!E10*-1 -> 0
B15: ２．売掛金の増加（－）・減少（＋）額 | C15: =CFワークシート!E11*-1 -> 0
B16: ３．棚卸資産の増加（－）・減少（＋）額 | C16: =CFワークシート!E13*-1 -> 0
B17: ４．その他の流動資産の増加（－）・減少（＋）額 | C17: =CFワークシート!E15*-1 -> 0
B18: ５．支払手形の増加（＋）・減少（－）額 | C18: =CFワークシート!J9 -> 0
B19: ６．買掛金の増加（＋）・減少（－）額 | C19: =CFワークシート!J10 -> 0
B20: ７．前受金の増加（＋）・減少（－）額 | C20: =CFワークシート!J12 -> 0
B21: ８．その他の流動負債の増加（＋）・減少（－）額 | C21: =CFワークシート!J14 -> 0
B22: ９．その他の固定負債の増加（＋）・減少（－）額 | C22: =CFワークシート!J19 -> 0
B23: １０．利益処分による役員賞与の支払（－）額 | C23: =CFワークシート!F60 -> 0
B24: （Ⅰの計） | C24: =SUM(C9:C23) -> 0
B25: Ⅱ 投資活動によるキャッシュ・フロー
B26: １．有価証券の購入（－）・売却（＋）額 | C26: =CFワークシート!E12*-1 -> 0
B27: ２．短期貸付金の貸付（－）・回収（＋）額 | C27: =CFワークシート!E14*-1 -> 0
B28: ３．土地の購入（－）・売却（＋）額 | C28: =CFワークシート!E18*-1 -> 0
B29: ４．減価償却資産の増加（－）・減少（＋）額 | C29: =(CFワークシート!E19+CFワークシート!D48)*-1 -> 0
B30: ５．建設仮勘定の増加（－）・減少（＋）額 | C30: =CFワークシート!E20*-1 -> 0
B31: ６．無形固定資産の増加（－）・減少（＋）額 | C31: =CFワークシート!E21*-1 -> 0
B32: ７．投資有価証券の購入（－）・売却（＋）額 | C32: =CFワークシート!E22*-1 -> 0
B33: ８．長期貸付金の貸付（－）・回収（＋）額 | C33: =CFワークシート!E23*-1 -> 0
B34: ９．その他の固定資産の増加（－）・減少（＋）額 | C34: =CFワークシート!E24*-1 -> 0
B35: １０．繰延資産の増加（－）・減少（＋）額 | C35: =CFワークシート!E27*-1 -> 0
B36: （Ⅱの計） | C36: =SUM(C26:C35) -> 0
B37: フリーキャッシュ・フロー（Ⅰ＋Ⅱ） | C37: =C24+C36 -> 0
B38: Ⅲ 財務活動によるキャッシュ・フロー
B39: １．短期借入金の増加（＋）・減少（－）額 | C39: =CFワークシート!J11 -> 0
B40: ２．長期借入金の増加（＋）・減少（－）額 | C40: =CFワークシート!J16 -> 0
B41: ３．社債の増加（＋）・返済（－）額 | C41: =CFワークシート!J17 -> 0
B42: ４．増資（＋）額 | C42: =CFワークシート!J22+CFワークシート!J23 -> 0
...

Sheet CF計算書②
B1: キャッシュ・フロー計算書（概算・参考）
B4: キャッシュ・フロー計算書②
B5: ='財務諸表（入力）'!G4 -> 2021年2月1日～2022年1月31日
C6: =CFワークシート!J7 -> （単位：千円） | E6: （単位：百万円）
B7: 項 目 | C7: 金 額 | E7: （単位：千円）
B8: Ⅰ 営業活動によるキャッシュ・フロー | E8: （単位：円）
B9: （１）当期純利益（＋） | C9: =CFワークシート②!D44 -> 0
B10: （２）非資金の費用項目
B11: １．減価償却費（＋） | C11: =CFワークシート②!D48 -> 0
B12: ２．諸引当金の増加（＋）・減少（－）額 | C12: =CFワークシート②!J13+CFワークシート②!J18-CFワークシート②!E16-CFワークシート②!E25 -> 0
B13: （３）回収・支払サイト
B14: １．受取手形の増加（－）・減少（＋）額 | C14: =CFワークシート②!E10*-1 -> 0
B15: ２．売掛金の増加（－）・減少（＋）額 | C15: =CFワークシート②!E11*-1 -> 0
B16: ３．棚卸資産の増加（－）・減少（＋）額 | C16: =CFワークシート②!E13*-1 -> 0
B17: ４．その他の流動資産の増加（－）・減少（＋）額 | C17: =CFワークシート②!E15*-1 -> 0
B18: ５．支払手形の増加（＋）・減少（－）額 | C18: =CFワークシート②!J9 -> 0
B19: ６．買掛金の増加（＋）・減少（－）額 | C19: =CFワークシート②!J10 -> 0
B20: ７．前受金の増加（＋）・減少（－）額 | C20: =CFワークシート②!J12 -> 0
B21: ８．その他の流動負債の増加（＋）・減少（－）額 | C21: =CFワークシート②!J14 -> 0
B22: ９．その他の固定負債の増加（＋）・減少（－）額 | C22: =CFワークシート②!J19 -> 0
B23: １０．利益処分による役員賞与の支払（－）額 | C23: =CFワークシート②!F60 -> 0
B24: （Ⅰの計） | C24: =SUM(C9:C23) -> 0
B25: Ⅱ 投資活動によるキャッシュ・フロー
B26: １．有価証券の購入（－）・売却（＋）額 | C26: =CFワークシート②!E12*-1 -> 0
B27: ２．短期貸付金の貸付（－）・回収（＋）額 | C27: =CFワークシート②!E14*-1 -> 0
B28: ３．土地の購入（－）・売却（＋）額 | C28: =CFワークシート②!E18*-1 -> 0
B29: ４．減価償却資産の増加（－）・減少（＋）額 | C29: =(CFワークシート②!E19+CFワークシート②!D48)*-1 -> 0
B30: ５．建設仮勘定の増加（－）・減少（＋）額 | C30: =CFワークシート②!E20*-1 -> 0
B31: ６．無形固定資産の増加（－）・減少（＋）額 | C31: =CFワークシート②!E21*-1 -> 0
B32: ７．投資有価証券の購入（－）・売却（＋）額 | C32: =CFワークシート②!E22*-1 -> 0
B33: ８．長期貸付金の貸付（－）・回収（＋）額 | C33: =CFワークシート②!E23*-1 -> 0
B34: ９．その他の固定資産の増加（－）・減少（＋）額 | C34: =CFワークシート②!E24*-1 -> 0
B35: １０．繰延資産の増加（－）・減少（＋）額 | C35: =CFワークシート②!E27*-1 -> 0
B36: （Ⅱの計） | C36: =SUM(C26:C35) -> 0
B37: フリーキャッシュ・フロー（Ⅰ＋Ⅱ） | C37: =C24+C36 -> 0
B38: Ⅲ 財務活動によるキャッシュ・フロー
B39: １．短期借入金の増加（＋）・減少（－）額 | C39: =CFワークシート②!J11 -> 0
B40: ２．長期借入金の増加（＋）・減少（－）額 | C40: =CFワークシート②!J16 -> 0
B41: ３．社債の増加（＋）・返済（－）額 | C41: =CFワークシート②!J17 -> 0
B42: ４．増資（＋）額 | C42: =CFワークシート②!J22+CFワークシート②!J23 -> 0
...

Sheet CFワークシート
B2: キャッシュ・フロー計算書のワークシート（入力用）
B7: １．貸借対照表の入力 | J7: （単位：千円） | L7: （単位：百万円）
B8: 項目 | C8: ='財務諸表（入力）'!G4 -> 2021年2月1日～2022年1月31日 | D8: ='財務諸表（入力）'!J4 -> 2022年2月1日～2023年1月31日 | E8: 増減 | F8: 項目 | H8: =C8 -> 2021年2月1日～2022年1月31日 | I8: =D8 -> 2022年2月1日～2023年1月31日 | J8: 増減 | L8: （単位：千円）
B9: 現金及び預金 | C9: ='財務諸表（入力）'!G6 -> 0 | D9: ='財務諸表（入力）'!J6 -> 0 | E9: =D9-C9 -> 0 | F9: 支払手形 | H9: ='財務諸表（入力）'!G51 -> 0 | I9: ='財務諸表（入力）'!J51 -> 0 | J9: =I9-H9 -> 0 | L9: （単位：円）
B10: 受取手形 | C10: ='財務諸表（入力）'!G8 -> 0 | D10: ='財務諸表（入力）'!J8 -> 0 | E10: =D10-C10 -> 0 | F10: 買掛金 | H10: ='財務諸表（入力）'!G52 -> 0 | I10: ='財務諸表（入力）'!J52 -> 0 | J10: =I10-H10 -> 0
B11: 売掛金 | C11: ='財務諸表（入力）'!G9 -> 0 | D11: ='財務諸表（入力）'!J9 -> 0 | E11: =D11-C11 -> 0 | F11: 短期借入金 | H11: ='財務諸表（入力）'!G53 -> 0 | I11: ='財務諸表（入力）'!J53 -> 0 | J11: =I11-H11 -> 0
B12: 有価証券 | E12: =D12-C12 -> 0 | F12: 前受金 | J12: =I12-H12 -> 0
B13: 棚卸資産 | C13: ='財務諸表（入力）'!G16 -> 0 | D13: ='財務諸表（入力）'!J16 -> 0 | E13: =D13-C13 -> 0 | F13: 引当金 | J13: =I13-H13 -> 0
B14: 短期貸付金 | E14: =D14-C14 -> 0 | F14: その他の流動負債 | H14: ='財務諸表（入力）'!G61-CFワークシート!H9-CFワークシート!H10-CFワークシート!H11-CFワークシート!H12-CFワークシート!H13 -> 0 | I14: ='財務諸表（入力）'!J61-CFワークシート!I9-CFワークシート!I10-CFワークシート!I11-CFワークシート!I12-CFワークシート!I13 -> 0 | J14: =I14-H14 -> 0
B15: その他の流動資産 | C15: ='財務諸表（入力）'!G28-CFワークシート!C9-CFワークシート!C10-CFワークシート!C11-CFワークシート!C12-CFワークシート!C13-CFワークシート!C14-CFワークシート!C16 -> 0 | D15: ='財務諸表（入力）'!J28-CFワークシート!D9-CFワークシート!D10-CFワークシート!D11-CFワークシート!D12-CFワークシート!D13-CFワークシート!D14-D16 -> 0 | E15: =D15-C15 -> 0 | F15: 流動負債合計 | H15: =SUM(H9:H14) -> 0 | I15: =SUM(I9:I14) -> 0 | J15: =I15-H15 -> 0
B16: 貸倒引当金 | C16: ='財務諸表（入力）'!G25 -> 0 | D16: ='財務諸表（入力）'!J25 -> 0 | E16: =D16-C16 -> 0 | F16: 長期借入金 | H16: ='財務諸表（入力）'!G62 -> 0 | I16: ='財務諸表（入力）'!J62 -> 0 | J16: =I16-H16 -> 0
B17: 流動資産合計 | C17: =SUM(C9:C16) -> 0 | D17: =SUM(D9:D16) -> 0 | E17: =D17-C17 -> 0 | F17: 社債 | H17: ='財務諸表（入力）'!G63 -> 0 | I17: ='財務諸表（入力）'!J63 -> 0 | J17: =I17-H17 -> 0
B18: 土地 | C18: ='財務諸表（入力）'!G34 -> 0 | D18: ='財務諸表（入力）'!J34 -> 0 | E18: =D18-C18 -> 0 | F18: 引当金 | J18: =I18-H18 -> 0
B19: 減価償却資産 | C19: ='財務諸表（入力）'!G37-'財務諸表（入力）'!G34-'財務諸表（入力）'!G35 -> 0 | D19: ='財務諸表（入力）'!J37-'財務諸表（入力）'!J34-'財務諸表（入力）'!J35 -> 0 | E19: =D19-C19 -> 0 | F19: その他の固定負債 | H19: ='財務諸表（入力）'!G69-CFワークシート!H16-CFワークシート!H17-CFワークシート!H18 -> 0 | I19: ='財務諸表（入力）'!J69-CFワークシート!I16-CFワークシート!I17-CFワークシート!I18 -> 0 | J19: =I19-H19 -> 0
B20: 建設仮勘定 | C20: ='財務諸表（入力）'!G35 -> 0 | D20: ='財務諸表（入力）'!J35 -> 0 | E20: =D20-C20 -> 0 | F20: 固定負債合計 | H20: =SUM(H16:H19) -> 0 | I20: =SUM(I16:I19) -> 0 | J20: =I20-H20 -> 0
B21: 無形固定資産 | C21: ='財務諸表（入力）'!G38 -> 0 | D21: ='財務諸表（入力）'!J38 -> 0 | E21: =D21-C21 -> 0 | F21: 負債合計 | H21: =H15+H20 -> 0 | I21: =I15+I20 -> 0 | J21: =I21-H21 -> 0
B22: 投資有価証券.子会社株式.出資金等 | E22: =D22-C22 -> 0 | F22: 資本金 | H22: ='財務諸表（入力）'!G71 -> 0 | I22: ='財務諸表（入力）'!J71 -> 0 | J22: =I22-H22 -> 0
B23: 長期貸付金 | E23: =D23-C23 -> 0 | F23: 資本剰余金 | H23: ='財務諸表（入力）'!G72 -> 0 | I23: ='財務諸表（入力）'!J72 -> 0 | J23: =I23-H23 -> 0
B24: その他の固定資産 | C24: ='財務諸表（入力）'!G47-CFワークシート!C22-CFワークシート!C23-CFワークシート!C25 -> 0 | D24: ='財務諸表（入力）'!J47-CFワークシート!D25-CFワークシート!D22-CFワークシート!D23 -> 0 | E24: =D24-C24 -> 0 | F24: 利益剰余金 | H24: ='財務諸表（入力）'!G73 -> 0 | I24: ='財務諸表（入力）'!J73 -> 0 | J24: =I24-H24 -> 0
B25: 貸倒引当金 | C25: ='財務諸表（入力）'!G45 -> 0 | D25: ='財務諸表（入力）'!J45 -> 0 | E25: =D25-C25 -> 0 | F25: 自己株式 | H25: ='財務諸表（入力）'!G77 -> 0 | I25: ='財務諸表（入力）'!J77 -> 0 | J25: =I25-H25 -> 0
B26: 固定資産合計 | C26: =SUM(C18:C25) -> 0 | D26: =SUM(D18:D25) -> 0 | E26: =D26-C26 -> 0 | F26: その他 | J26: =I26-H26 -> 0
B27: 繰延資産合計 | C27: ='財務諸表（入力）'!G48 -> 0 | D27: ='財務諸表（入力）'!J48 -> 0 | E27: =D27-C27 -> 0 | F27: 純資産合計 | H27: =SUM(H22:H26) -> 0 | I27: =SUM(I22:I26) -> 0 | J27: =I27-H27 -> 0
B28: 資産合計 | C28: =C17+C26+C27 -> 0 | D28: =D17+D26+D27 -> 0 | E28: =D28-C28 -> 0 | F28: 負債･純資産合計 | H28: =H21+H27 -> 0 | I28: =I21+I27 -> 0 | J28: =I28-H28 -> 0
B29: （注）有利子負債は、短期借入金又は長期借入金に含める。
B30: ２．損益計算書の入力 | E30: =J7 -> （単位：千円）
B31: 項目 | C31: =C8 -> 2021年2月1日～2022年1月31日 | D31: =D8 -> 2022年2月1日～2023年1月31日 | E31: 増減
B32: 売上高 | C32: ='財務諸表（入力）'!G129 -> 0 | D32: ='財務諸表（入力）'!J129 -> 0 | E32: =D32-C32 -> 0
B33: 売上原価 | C33: ='財務諸表（入力）'!G136 -> 0 | D33: ='財務諸表（入力）'!J136 -> 0 | E33: =D33-C33 -> 0
B34: 売上総利益 | C34: =C32-C33 -> 0 | D34: =D32-D33 -> 0 | E34: =D34-C34 -> 0
B35: 販売費及び一般管理費 | C35: ='財務諸表（入力）'!G156 -> 0 | D35: ='財務諸表（入力）'!J156 -> 0 | E35: =D35-C35 -> 0
B36: 営業利益 | C36: =C34-C35 -> 0 | D36: =D34-D35 -> 0 | E36: =D36-C36 -> 0
